Workbook

Sheet check
A1: Maximum 20 bars per side
A2: Column P-M Calculation | AQ2: theta | AR2: Mn | AS2: Pn | AT2: fiMn_max | AU2: fiPn_max
B3: Column X-dir size B = | C3: 50 | D3: cm | AQ3: 90 | AR3: 0 | AS3: 1686.1 | AT3: 0 | AU3: 876.8
B4: Column Y-dir size D = | C4: 40 | D4: cm | F4: A= | G4: =C3*C4 -> 2000 | H4: cm^2 | S4: 鋼筋 | AQ4: 90 | AR4: 0 | AS4: 1686.1 | AT4: 0 | AU4: 876.8
B5: Concrete strength f'c = | C5: 280 | D5: kgf/cm^2 | F5: β1= | G5: =IF(IF(C5>280,0.85-0.05*(C5-280)/70,0.85)<0.65,0.65,IF(C5>280,0.85-0.05*(C5-280)/70,0.85)) -> 0.85 | S5: 號數 | T5: 面積 | U5: 直徑(cm) | AQ5: 90 | AR5: 0 | AS5: 1686.1 | AT5: 0 | AU5: 876.8
B6: Bars parallel to width (X-dir) | C6: 4 | D6: (horizontal in analysis fig) | F6: Spaces | G6: =C6-1 -> 3 | H6: Bar spacing | I6: =(C3-C11*2)/G6 -> 12.666667 | J6: cm | S6: 3 | T6: 0.71 | U6: 0.953 | AQ6: 90 | AR6: 0.4 | AS6: 1684.6 | AT6: 0.2 | AU6: 876.8
B7: Bars parallel to depth (Y-dir) | C7: 4 | D7: (vertical in analysis fig) | F7: Spaces | G7: =C7-1 -> 3 | H7: Bar spacing | I7: =(C4-C11*2)/G7 -> 9.3333333 | J7: cm | S7: 4 | T7: 1.27 | U7: 1.27 | AQ7: 90 | AR7: 2.8 | AS7: 1673.3 | AT7: 1.5 | AU7: 876.8
B8: Total number of bars | C8: =bar!C1 -> 12 | D8: See rebar layout figure | S8: 5 | T8: 1.98 | U8: 15.9 | AQ8: 90 | AR8: 5.4 | AS8: 1660 | AT8: 2.9 | AU8: 876.8
B9: As= | C9: =bar!F1 -> 34.2 | D9: cm^2 | F9: Steel ratio ρ = | G9: =C9/G4 -> 0.0171 | S9: 6 | T9: 2.85 | U9: 1.91 | AQ9: 90 | AR9: 8 | AS9: 1646.3 | AT9: 4.3 | AU9: 876.8
B10: Yield strength fy = | C10: 4200 | D10: kgf/cm^2 | F10: α= | G10: =IF(C12=1,0.85,0.8) -> 0.8 | S10: 7 | T10: 3.87 | U10: 2.22 | AQ10: 90 | AR10: 10.6 | AS10: 1632 | AT10: 5.7 | AU10: 876.8
B11: Cover to bar centroid d' = | C11: 6 | D11: cm | F11: εy= | G11: =C10/2040000 -> 0.0020588235 | S11: 8 | T11: 5.07 | U11: 2.54 | AQ11: 90 | AR11: 13.1 | AS11: 1617.3 | AT11: 7.1 | AU11: 876.8
B12: Spiral=1, Tie=2 | C12: 2 | S12: 9 | T12: 6.45 | U12: 2.87 | AQ12: 90 | AR12: 15.5 | AS12: 1602.6 | AT12: 8.5 | AU12: 876.8
B13: Seismic angle θ = | C13: 0 | D13: ° (clockwise positive) | F13: Radians = | G13: =C13/180*PI() -> 0 | AQ13: 90 | AR13: 18 | AS13: 1587.9 | AT13: 9.9 | AU13: 876.8
B14: Demand axial Pu = | C14: 10 | D14: tf/column | F14: εmax= | G14: 0.005 | S14: 10 | T14: 8.17 | U14: 3.22 | AQ14: 90 | AR14: 20.5 | AS14: 1573.1 | AT14: 11.4 | AU14: 876.8
B15: Demand moment Mu = | C15: 10 | D15: tf-m/column | F15: εc= | G15: 0.003 | S15: 11 | T15: 10.01 | U15: 3.58 | AQ15: 90 | AR15: 23 | AS15: 1558.4 | AT15: 12.9 | AU15: 876.8
AQ16: 90 | AR16: 25.5 | AS16: 1543.7 | AT16: 14.5 | AU16: 876.8
AQ17: 90 | AR17: 27.9 | AS17: 1529 | AT17: 16 | AU17: 876.8
AQ18: 90 | AR18: 30.4 | AS18: 1514.3 | AT18: 17.6 | AU18: 876.8
AQ19: 90 | AR19: 32.9 | AS19: 1499.6 | AT19: 19.2 | AU19: 876.8
B20: Check result: | C20: Moment check | D20: =IF(M22<0,"NG!!!!","OK") -> OK | AQ20: 90 | AR20: 35.2 | AS20: 1484 | AT20: 20.8 | AU20: 876.8
A21: RC Column P-M Calculation | Y21: FIBER | AI21: FIBER | AQ21: 90 | AR21: 45.7 | AS21: 1439.5 | AT21: 27.9 | AU21: 876.8
B22: rebar | G22: 分析值斜率 | H22: =C14/C15 -> 1 | K22: 分析值均方和 | L22: =(C15^2+C14^2)^0.5 -> 14.142136 | M22: =SIGN(MAX(M24:M34)-L22) -> 1 | S22: Curve #1 0 deg | Y22: Curve #1 0 deg | AD22: Curve #1 0 deg | AI22: Curve #1 0 deg | AQ22: 90 | AR22: 64.8 | AS22: 1360.8 | AT22: 41.8 | AU22: 876.8
B23: no | C23: M | D23: P | E23: ψ | F23: ψMn | G23: ψPn | H23: m | I23: a | J23: mm | K23: pp | N23: ψPn | O23: ψMnx | P23: ψMny | S23: Point | T23: P tonf | U23: M2 tonf-m | V23: M3 tonf-m | Y23: Point | Z23: P tonf | AA23: M2 tonf-m | AB23: M3 tonf-m | AD23: Point | AE23: P tonf | AF23: M2 tonf-m | AG23: M3 tonf-m | AI23: Point | AJ23: P tonf | AK23: M2 tonf-m | AL23: M3 tonf-m | AQ23: 90 | AR23: 77.9 | AS23: 1299 | AT23: 50.6 | AU23: 844.4
B24: 0 | C24: =INDIRECT("R"&B24&"!B97") -> 8.8817842e-16 | D24: =INDIRECT("R"&B24&"!C97") -> 611.5004 | E24: =INDIRECT("R"&B24&"!D97") -> 0.65 | F24: =C24*$E24 -> 5.7731597e-16 | G24: =G25 -> 317.98021 | H24: =IFERROR(SLOPE(G24:G25,F24:F25),0) -> 0 | I24: =IFERROR(INTERCEPT(G24:G25,F24:F25),0) -> 317.98021 | J24: =IF(H24=0,0,-1*I24/(H24-$H$22)) -> 0 | K24: =H24*J24+I24 -> 317.98021 | L24: =IF(AND(J24>MIN(F24,F25),J24<MAX(F24,F25)),J24,0) -> 0 | M24: =IF(L24=0,IF(SUM(L24:L34)=0,(L24^2+K24^2)^0.5,0),0) -> 317.98021 | N24: =G24 -> 317.98021 | O24: =COS(G$13)*F24 -> 5.7731597e-16 | P24: =SIN(G$13)*F24 -> 0 | S24: 1 | T24: =AE24 -> 2836.9324 | U24: 0 | V24: =(AF24^2+AG24^2)^0.5 -> 0 | Y24: 1 | Z24: =AJ24 -> 5455.6393 | AA24: 0 | AB24: =(AK24^2+AL24^2)^0.5 -> 0 | AD24: 1 | AE24: 2836.9324 | AF24: 0 | AG24: 0 | AI24: 1 | AJ24: 5455.6393 | AK24: 0 | AL24: 0 | AQ24: 90 | AR24: 90.9 | AS24: 1231.7 | AT24: 59.1 | AU24: 800.6
B25: 0 | C25: =C24 -> 8.8817842e-16 | D25: =D24 -> 611.5004 | E25: =E24 -> 0.65 | F25: =(F26-F24)*(G25-D24*E24)/(G26-D24*E24) -> 14.125174 | G25: =G10*D25*E25 -> 317.98021 | H25: =IFERROR(SLOPE(G25:G26,F25:F26),0) -> -5.6278991 | I25: =IFERROR(INTERCEPT(G25:G26,F25:F26),0) -> 397.47526 | J25: =-1*I25/(H25-$H$22) -> 59.970023 | K25: =H25*J25+I25 -> 59.970023 | L25: =IF(AND(J25>MIN(F25,F26),J25<MAX(F25,F26)),J25,0) -> 0 | M25: =IF(L25=0,0,(L25^2+K25^2)^0.5) -> 0 | N25: =G25 -> 317.98021 | O25: =COS(G$13)*F25 -> 14.125174 | P25: =SIN(G$13)*F25 -> 0 | S25: 2 | T25: =AE25 -> 2782.772 | U25: 0 | V25: =(AF25^2+AG25^2)^0.5 -> 221.21285 | Y25: 2 | Z25: =AJ25 -> 3685.8443 | AA25: 0 | AB25: =(AK25^2+AL25^2)^0.5 -> 584.31269 | AD25: 2 | AE25: 2782.772 | AF25: 198.1945 | AG25: 98.2551 | AI25: 2 | AJ25: 3685.8443 | AK25: 537.729 | AL25: 228.6238 | AQ25: 90 | AR25: 101.5 | AS25: 1170.1 | AT25: 66 | AU25: 760.5
B26: 1 | C26: =INDIRECT("R"&B26&"!B97") -> 30.159454 | D26: =INDIRECT("R"&B26&"!C97") -> 441.76604 | E26: =INDIRECT("R"&B26&"!D97") -> 0.65 | F26: =C26*$E26 -> 19.603645 | G26: =IF(D26*$E26>G25,G25,D26*$E26) -> 287.14792 | H26: =IFERROR(SLOPE(G26:G27,F26:F27),0) -> -7.7001909 | I26: =IFERROR(INTERCEPT(G26:G27,F26:F27),0) -> 438.09973 | J26: =-1*I26/(H26-$H$22) -> 50.355186 | K26: =H26*J26+I26 -> 50.355186 | L26: =IF(AND(J26>MIN(F26,F27),J26<MAX(F26,F27)),J26,0) -> 0 | M26: =IF(L26=0,0,(L26^2+K26^2)^0.5) -> 0 | N26: =G26 -> 287.14792 | O26: =COS(G$13)*F26 -> 19.603645 | P26: =SIN(G$13)*F26 -> 0 | S26: 3 | T26: =AE26 -> 2452.1727 | U26: 0 | V26: =(AF26^2+AG26^2)^0.5 -> 334.69322 | Y26: 3 | Z26: =AJ26 -> 3144.1805 | AA26: 0 | AB26: =(AK26^2+AL26^2)^0.5 -> 695.34194 | AD26: 3 | AE26: 2452.1727 | AF26: 300.1362 | AG26: 148.1142 | AI26: 3 | AJ26: 3144.1805 | AK26: 645.9697 | AL26: 257.3394 | AQ26: 90 | AR26: 110.2 | AS26: 1114.2 | AT26: 71.6 | AU26: 724.2
B27: 2 | C27: =INDIRECT("R"&B27&"!B97") -> 30.498931 | D27: =INDIRECT("R"&B27&"!C97") -> 439.152 | E27: =INDIRECT("R"&B27&"!D97") -> 0.65 | F27: =C27*$E27 -> 19.824305 | G27: =IF(D27*$E27>G26,G26,D27*$E27) -> 285.4488 | H27: =IFERROR(SLOPE(G27:G28,F27:F28),0) -> -8.2705698 | I27: =IFERROR(INTERCEPT(G27:G28,F27:F28),0) -> 449.4071 | J27: =-1*I27/(H27-$H$22) -> 48.47675 | K27: =H27*J27+I27 -> 48.47675 | L27: =IF(AND(J27>MIN(F27,F28),J27<MAX(F27,F28)),J27,0) -> 0 | M27: =IF(L27=0,0,(L27^2+K27^2)^0.5) -> 0 | N27: =G27 -> 285.4488 | O27: =COS(G$13)*F27 -> 19.824305 | P27: =SIN(G$13)*F27 -> 0 | S27: 4 | T27: =AE27 -> 1971.6744 | U27: 0 | V27: =(AF27^2+AG27^2)^0.5 -> 451.02977 | Y27: 4 | Z27: =AJ27 -> 2541.7722 | AA27: 0 | AB27: =(AK27^2+AL27^2)^0.5 -> 785.44711 | AD27: 4 | AE27: 1971.6744 | AF27: 419.5988 | AG27: 165.4228 | AI27: 4 | AJ27: 2541.7722 | AK27: 739.7663 | AL27: 263.9564 | AQ27: 90 | AR27: 117.7 | AS27: 1061.1 | AT27: 76.5 | AU27: 689.7
B28: 3 | C28: =INDIRECT("R"&B28&"!B97") -> 33.70582 | D28: =INDIRECT("R"&B28&"!C97") -> 412.6292 | E28: =INDIRECT("R"&B28&"!D97") -> 0.65 | F28: =C28*$E28 -> 21.908783 | G28: =IF(D28*$E28>G27,G27,D28*$E28) -> 268.20898 | H28: =IFERROR(SLOPE(G28:G29,F28:F29),0) -> -9.4927201 | I28: =IFERROR(INTERCEPT(G28:G29,F28:F29),0) -> 476.18292 | J28: =-1*I28/(H28-$H$22) -> 45.382219 | K28: =H28*J28+I28 -> 45.382219 | L28: =IF(AND(J28>MIN(F28,F29),J28<MAX(F28,F29)),J28,0) -> 0 | M28: =IF(L28=0,0,(L28^2+K28^2)^0.5) -> 0 | N28: =G28 -> 268.20898 | O28: =COS(G$13)*F28 -> 21.908783 | P28: =SIN(G$13)*F28 -> 0 | S28: 5 | T28: =AE28 -> 1405.6579 | U28: 0 | V28: =(AF28^2+AG28^2)^0.5 -> 541.13569 | Y28: 5 | Z28: =AJ28 -> 1830.6063 | AA28: 0 | AB28: =(AK28^2+AL28^2)^0.5 -> 863.49154 | AD28: 5 | AE28: 1405.6579 | AF28: 507.8535 | AG28: 186.8493 | AI28: 5 | AJ28: 1830.6063 | AK28: 802.1481 | AL28: 319.6499 | AQ28: 90 | AR28: 122.8 | AS28: 1021.4 | AT28: 79.8 | AU28: 663.9
B29: 4 | C29: =INDIRECT("R"&B29&"!B97") -> 36.582698 | D29: =INDIRECT("R"&B29&"!C97") -> 385.3198 | E29: =INDIRECT("R"&B29&"!D97") -> 0.65 | F29: =C29*$E29 -> 23.778754 | G29: =IF(D29*$E29>G28,G28,D29*$E29) -> 250.45787 | H29: =IFERROR(SLOPE(G29:G30,F29:F30),0) -> -11.007032 | I29: =IFERROR(INTERCEPT(G29:G30,F29:F30),0) -> 512.19137 | J29: =-1*I29/(H29-$H$22) -> 42.657617 | K29: =H29*J29+I29 -> 42.657617 | L29: =IF(AND(J29>MIN(F29,F30),J29<MAX(F29,F30)),J29,0) -> 0 | M29: =IF(L29=0,0,(L29^2+K29^2)^0.5) -> 0 | N29: =G29 -> 250.45787 | O29: =COS(G$13)*F29 -> 23.778754 | P29: =SIN(G$13)*F29 -> 0 | S29: 6 | T29: =AE29 -> 698.0935 | U29: 0 | V29: =(AF29^2+AG29^2)^0.5 -> 615.86765 | Y29: 6 | Z29: =AJ29 -> 994.7321 | AA29: 0 | AB29: =(AK29^2+AL29^2)^0.5 -> 926.3807 | AD29: 6 | AE29: 698.0935 | AF29: 575.618 | AG29: 218.9906 | AI29: 6 | AJ29: 994.7321 | AK29: 863.5252 | AL29: 335.4183 | AQ29: 90 | AR29: 128.4 | AS29: 974.1 | AT29: 83.5 | AU29: 633.2
B30: 5 | C30: =INDIRECT("R"&B30&"!B97") -> 39.149541 | D30: =INDIRECT("R"&B30&"!C97") -> 357.06648 | E30: =INDIRECT("R"&B30&"!D97") -> 0.65 | F30: =C30*$E30 -> 25.447201 | G30: =IF(D30*$E30>G29,G29,D30*$E30) -> 232.09321 | H30: =IFERROR(SLOPE(G30:G31,F30:F31),0) -> -11.588718 | I30: =IFERROR(INTERCEPT(G30:G31,F30:F31),0) -> 526.99366 | J30: =-1*I30/(H30-$H$22) -> 41.862376 | K30: =H30*J30+I30 -> 41.862376 | L30: =IF(AND(J30>MIN(F30,F31),J30<MAX(F30,F31)),J30,0) -> 0 | M30: =IF(L30=0,0,(L30^2+K30^2)^0.5) -> 0 | N30: =G30 -> 232.09321 | O30: =COS(G$13)*F30 -> 25.447201 | P30: =SIN(G$13)*F30 -> 0 | S30: 7 | T30: =AE30 -> 182.414 | U30: 0 | V30: =(AF30^2+AG30^2)^0.5 -> 726.34363 | Y30: 7 | Z30: =AJ30 -> 161.0403 | AA30: 0 | AB30: =(AK30^2+AL30^2)^0.5 -> 910.40671 | AD30: 7 | AE30: 182.414 | AF30: 680.9437 | AG30: 252.7662 | AI30: 7 | AJ30: 161.0403 | AK30: 849.8862 | AL30: 326.3952 | AQ30: 90 | AR30: 133.5 | AS30: 926.8 | AT30: 86.8 | AU30: 602.4
B31: 6 | C31: =INDIRECT("R"&B31&"!B97") -> 41.569386 | D31: =INDIRECT("R"&B31&"!C97") -> 329.02357 | E31: =INDIRECT("R"&B31&"!D97") -> 0.65 | F31: =C31*$E31 -> 27.020101 | G31: =IF(D31*$E31>G30,G30,D31*$E31) -> 213.86532 | H31: =IFERROR(SLOPE(G31:G32,F31:F32),0) -> -15.057751 | I31: =IFERROR(INTERCEPT(G31:G32,F31:F32),0) -> 620.72729 | J31: =-1*I31/(H31-$H$22) -> 38.655928 | K31: =H31*J31+I31 -> 38.655928 | L31: =IF(AND(J31>MIN(F31,F32),J31<MAX(F31,F32)),J31,0) -> 0 | M31: =IF(L31=0,0,(L31^2+K31^2)^0.5) -> 0 | N31: =G31 -> 213.86532 | O31: =COS(G$13)*F31 -> 27.020101 | P31: =SIN(G$13)*F31 -> 0 | S31: 8 | T31: =AE31 -> -453.1236 | U31: 0 | V31: =(AF31^2+AG31^2)^0.5 -> 719.53716 | Y31: 8 | Z31: =AJ31 -> -565.5307 | AA31: 0 | AB31: =(AK31^2+AL31^2)^0.5 -> 765.28859 | AD31: 8 | AE31: -453.1236 | AF31: 659.4343 | AG31: 287.8891 | AI31: 8 | AJ31: -565.5307 | AK31: 685.7834 | AL31: 339.6583 | AQ31: 90 | AR31: 137.7 | AS31: 885.1 | AT31: 89.5 | AU31: 575.3
B32: 7 | C32: =INDIRECT("R"&B32&"!B97") -> 43.615522 | D32: =INDIRECT("R"&B32&"!C97") -> 298.21337 | E32: =INDIRECT("R"&B32&"!D97") -> 0.65 | F32: =C32*$E32 -> 28.350089 | G32: =IF(D32*$E32>G31,G31,D32*$E32) -> 193.83869 | H32: =IFERROR(SLOPE(G32:G33,F32:F33),0) -> -17.701608 | I32: =IFERROR(INTERCEPT(G32:G33,F32:F33),0) -> 695.68085 | J32: =-1*I32/(H32-$H$22) -> 37.198986 | K32: =H32*J32+I32 -> 37.198986 | L32: =IF(AND(J32>MIN(F32,F33),J32<MAX(F32,F33)),J32,0) -> 0 | M32: =IF(L32=0,0,(L32^2+K32^2)^0.5) -> 0 | N32: =G32 -> 193.83869 | O32: =COS(G$13)*F32 -> 28.350089 | P32: =SIN(G$13)*F32 -> 0 | S32: 9 | T32: =AE32 -> -1127.5517 | U32: 0 | V32: =(AF32^2+AG32^2)^0.5 -> 510.42997 | Y32: 9 | Z32: =AJ32 -> -1349.5075 | AA32: 0 | AB32: =(AK32^2+AL32^2)^0.5 -> 507.8755 | AD32: 9 | AE32: -1127.5517 | AF32: 442.6745 | AG32: 254.1221 | AI32: 9 | AJ32: -1349.5075 | AK32: 440.29 | AL32: 253.1447 | AQ32: 90 | AR32: 141.6 | AS32: 843.5 | AT32: 92 | AU32: 548.3
B33: 8 | C33: =INDIRECT("R"&B33&"!B97") -> 45.455669 | D33: =INDIRECT("R"&B33&"!C97") -> 265.6398 | E33: =INDIRECT("R"&B33&"!D97") -> 0.65 | F33: =C33*$E33 -> 29.546185 | G33: =IF(D33*$E33>G32,G32,D33*$E33) -> 172.66587 | H33: =IFERROR(SLOPE(G33:G34,F33:F34),0) -> -20.538807 | I33: =IFERROR(INTERCEPT(G33:G34,F33:F34),0) -> 779.50927 | J33: =-1*I33/(H33-$H$22) -> 36.190921 | K33: =H33*J33+I33 -> 36.190921 | L33: =IF(AND(J33>MIN(F33,F34),J33<MAX(F33,F34)),J33,0) -> 0 | M33: =IF(L33=0,0,(L33^2+K33^2)^0.5) -> 0 | N33: =G33 -> 172.66587 | O33: =COS(G$13)*F33 -> 29.546185 | P33: =SIN(G$13)*F33 -> 0 | S33: 10 | T33: =AE33 -> -1878.6272 | U33: 0 | V33: =(AF33^2+AG33^2)^0.5 -> 207.70351 | Y33: 10 | Z33: =AJ33 -> -2140.3996 | AA33: 0 | AB33: =(AK33^2+AL33^2)^0.5 -> 194.31122 | AD33: 10 | AE33: -1878.6272 | AF33: 145.4742 | AG33: 148.2498 | AI33: 10 | AJ33: -2140.3996 | AK33: 137.0151 | AL33: 137.7814 | AQ33: 90 | AR33: 144.9 | AS33: 804.7 | AT33: 94.2 | AU33: 523.1
B34: 9 | C34: =INDIRECT("R"&B34&"!B97") -> 47.150892 | D34: =INDIRECT("R"&B34&"!C97") -> 230.82195 | E34: =INDIRECT("R"&B34&"!D97") -> 0.65 | F34: =C34*$E34 -> 30.64808 | G34: =IF(D34*$E34>G33,G33,D34*$E34) -> 150.03426 | H34: =IFERROR(SLOPE(G34:G35,F34:F35),0) -> -13.390507 | I34: =IFERROR(INTERCEPT(G34:G35,F34:F35),0) -> 560.42761 | J34: =-1*I34/(H34-$H$22) -> 38.944256 | K34: =H34*J34+I34 -> 38.944256 | L34: =IF(AND(J34>MIN(F34,F35),J34<MAX(F34,F35)),J34,0) -> 0 | M34: =IF(L34=0,0,(L34^2+K34^2)^0.5) -> 0 | N34: =G34 -> 150.03426 | O34: =COS(G$13)*F34 -> 30.64808 | P34: =SIN(G$13)*F34 -> 0 | S34: 11 | T34: =AE34 -> -2219.8176 | U34: 0 | V34: =(AF34^2+AG34^2)^0.5 -> 0 | Y34: 11 | Z34: =AJ34 -> -2466.464 | AA34: 0 | AB34: =(AK34^2+AL34^2)^0.5 -> 0 | AD34: 11 | AE34: -2219.8176 | AF34: 0 | AG34: 0 | AI34: 11 | AJ34: -2466.464 | AK34: 0 | AL34: 0 | AQ34: 90 | AR34: 148 | AS34: 766 | AT34: 96.2 | AU34: 497.9
B35: 10 | C35: =INDIRECT("R"&B35&"!B97") -> 47.80938 | D35: =INDIRECT("R"&B35&"!C97") -> 198.2302 | E35: =INDIRECT("R"&B35&"!D97") -> 0.66843137 | F35: =C35*$E35 -> 31.95729 | G35: =IF(D35*$E35>G34,G34,D35*$E35) -> 132.50328 | H35: =IFERROR(SLOPE(G35:G36,F35:F36),0) -> -6.1164762 | I35: =IFERROR(INTERCEPT(G35:G36,F35:F36),0) -> 327.96928 | J35: =-1*I35/(H35-$H$22) -> 46.085911 | K35: =H35*J35+I35 -> 46.085911 | L35: =IF(AND(J35>MIN(F35,F36),J35<MAX(F35,F36)),J35,0) -> 0 | M35: =IF(L35=0,0,(L35^2+K35^2)^0.5) -> 0 | N35: =G35 -> 132.50328 | O35: =COS(G$13)*F35 -> 31.95729 | P35: =SIN(G$13)*F35 -> 0 | AQ35: 90 | AR35: 150.8 | AS35: 730.1 | AT35: 98 | AU35: 474.5
B36: 11 | C36: =INDIRECT("R"&B36&"!B97") -> 46.916946 | D36: =INDIRECT("R"&B36&"!C97") -> 170.2482 | E36: =INDIRECT("R"&B36&"!D97") -> 0.71732026 | F36: =C36*$E36 -> 33.654476 | G36: =IF(D36*$E36>G35,G35,D36*$E36) -> 122.12248 | H36: =IFERROR(SLOPE(G36:G37,F36:F37),0) -> -5.8099654 | I36: =IFERROR(INTERCEPT(G36:G37,F36:F37),0) -> 317.65383 | J36: =-1*I36/(H36-$H$22) -> 46.645439 | K36: =H36*J36+I36 -> 46.645439 | L36: =IF(AND(J36>MIN(F36,F37),J36<MAX(F36,F37)),J36,0) -> 0 | M36: =IF(L36=0,0,(L36^2+K36^2)^0.5) -> 0 | N36: =G36 -> 122.12248 | O36: =COS(G$13)*F36 -> 33.654476 | P36: =SIN(G$13)*F36 -> 0 | AQ36: 90 | AR36: 153.3 | AS36: 694.2 | AT36: 99.6 | AU36: 451.2
B37: 12 | C37: =INDIRECT("R"&B37&"!B97") -> 45.849558 | D37: =INDIRECT("R"&B37&"!C97") -> 141.6848 | E37: =INDIRECT("R"&B37&"!D97") -> 0.77843137 | F37: =C37*$E37 -> 35.690734 | G37: =IF(D37*$E37>G36,G36,D37*$E37) -> 110.29189 | H37: =IFERROR(SLOPE(G37:G38,F37:F38),0) -> -9.4010885 | I37: =IFERROR(INTERCEPT(G37:G38,F37:F38),0) -> 445.82364 | J37: =-1*I37/(H37-$H$22) -> 42.863172 | K37: =H37*J37+I37 -> 42.863172 | L37: =IF(AND(J37>MIN(F37,F38),J37<MAX(F37,F38)),J37,0) -> 0 | M37: =IF(L37=0,0,(L37^2+K37^2)^0.5) -> 0 | N37: =G37 -> 110.29189 | O37: =COS(G$13)*F37 -> 35.690734 | P37: =SIN(G$13)*F37 -> 0 | AQ37: 90 | AR37: 155.6 | AS37: 661.1 | AT37: 101.2 | AU37: 429.7
B38: 13 | C38: =INDIRECT("R"&B38&"!B97") -> 43.570896 | D38: =INDIRECT("R"&B38&"!C97") -> 110.59874 | E38: =INDIRECT("R"&B38&"!D97") -> 0.8570028 | F38: =C38*$E38 -> 37.34038 | G38: =IF(D38*$E38>G37,G37,D38*$E38) -> 94.783432 | H38: =IFERROR(SLOPE(G38:G39,F38:F39),0) -> 18.471446 | I38: =IFERROR(INTERCEPT(G38:G39,F38:F39),0) -> -594.94738 | J38: =-1*I38/(H38-$H$22) -> 34.052555 | K38: =H38*J38+I38 -> 34.052555 | L38: =IF(AND(J38>MIN(F38,F39),J38<MAX(F38,F39)),J38,0) -> 0 | M38: =IF(L38=0,0,(L38^2+K38^2)^0.5) -> 0 | N38: =G38 -> 94.783432 | O38: =COS(G$13)*F38 -> 37.34038 | P38: =SIN(G$13)*F38 -> 0 | AQ38: 90 | AR38: 157.8 | AS38: 630.5 | AT38: 102.6 | AU38: 409.8
B39: 14 | C39: =INDIRECT("R"&B39&"!B97") -> 40.128588 | D39: =INDIRECT("R"&B39&"!C97") -> 80.1804 | E39: =INDIRECT("R"&B39&"!D97") -> 0.9 | F39: =C39*$E39 -> 36.115729 | G39: =IF(D39*$E39>G38,G38,D39*$E39) -> 72.16236 | H39: =IFERROR(SLOPE(G39:G40,F39:F40),0) -> 7.9619873 | I39: =IFERROR(INTERCEPT(G39:G40,F39:F40),0) -> -215.39061 | J39: =-1*I39/(H39-$H$22) -> 30.938093 | K39: =H39*J39+I39 -> 30.938093 | L39: =IF(AND(J39>MIN(F39,F40),J39<MAX(F39,F40)),J39,0) -> 0 | M39: =IF(L39=0,0,(L39^2+K39^2)^0.5) -> 0 | N39: =G39 -> 72.16236 | O39: =COS(G$13)*F39 -> 36.115729 | P39: =SIN(G$13)*F39 -> 0 | AQ39: 90 | AR39: 159.8 | AS39: 597.4 | AT39: 103.9 | AU39: 388.3
B40: 15 | C40: =INDIRECT("R"&B40&"!B97") -> 35.796292 | D40: =INDIRECT("R"&B40&"!C97") -> 45.68672 | E40: =INDIRECT("R"&B40&"!D97") -> 0.9 | F40: =C40*$E40 -> 32.216663 | G40: =IF(D40*$E40>G39,G39,D40*$E40) -> 41.118048 | H40: =IFERROR(SLOPE(G40:G41,F40:F41),0) -> 6.835751 | I40: =IFERROR(INTERCEPT(G40:G41,F40:F41),0) -> -179.10704 | J40: =-1*I40/(H40-$H$22) -> 30.691343 | K40: =H40*J40+I40 -> 30.691343 | L40: =IF(AND(J40>MIN(F40,F41),J40<MAX(F40,F41)),J40,0) -> 30.691343 | M40: =IF(L40=0,0,(L40^2+K40^2)^0.5) -> 43.404114 | N40: =G40 -> 41.118048 | O40: =COS(G$13)*F40 -> 32.216663 | P40: =SIN(G$13)*F40 -> 0 | AQ40: 90 | AR40: 161.7 | AS40: 567.2 | AT40: 105.1 | AU40: 368.7
...

Sheet rebarps
B1: B(X) | C1: 1 | D1: 2 | E1: 3 | F1: 4 | G1: 5 | H1: 6 | I1: 7 | J1: 8 | K1: 9 | L1: 10 | M1: 11 | N1: 12 | O1: 13 | P1: 14 | Q1: 15 | R1: 16 | S1: 17 | T1: 18 | U1: 19 | V1: 20
A2: D(Y) | C2: =IF(C$1>check!$C$6,0,check!$C$11+(rebarps!C$1-1)*check!$I$6) -> 6 | D2: =IF(D$1>check!$C$6,0,check!$C$11+(rebarps!D$1-1)*check!$I$6) -> 18.666667 | E2: =IF(E$1>check!$C$6,0,check!$C$11+(rebarps!E$1-1)*check!$I$6) -> 31.333333 | F2: =IF(F$1>check!$C$6,0,check!$C$11+(rebarps!F$1-1)*check!$I$6) -> 44 | G2: =IF(G$1>check!$C$6,0,check!$C$11+(rebarps!G$1-1)*check!$I$6) -> 0 | H2: =IF(H$1>check!$C$6,0,check!$C$11+(rebarps!H$1-1)*check!$I$6) -> 0 | I2: =IF(I$1>check!$C$6,0,check!$C$11+(rebarps!I$1-1)*check!$I$6) -> 0 | J2: =IF(J$1>check!$C$6,0,check!$C$11+(rebarps!J$1-1)*check!$I$6) -> 0 | ... V2: =IF(V$1>check!$C$6,0,check!$C$11+(rebarps!V$1-1)*check!$I$6) -> 0
A3: 1 | B3: =IF($A3>check!$C$7,0,check!$C$11+(rebarps!$A3-1)*check!$I$7) -> 6 | C3: 6 | D3: 6 | E3: 6 | F3: 6
A4: 2 | B4: =IF($A4>check!$C$7,0,check!$C$11+(rebarps!$A4-1)*check!$I$7) -> 15.333333 | C4: 6 | F4: 6
A5: 3 | B5: =IF($A5>check!$C$7,0,check!$C$11+(rebarps!$A5-1)*check!$I$7) -> 24.666667 | C5: 6 | F5: 6
A6: 4 | B6: =IF($A6>check!$C$7,0,check!$C$11+(rebarps!$A6-1)*check!$I$7) -> 34 | C6: 6 | D6: 6 | E6: 6 | F6: 6
A7: 5 | B7: =IF($A7>check!$C$7,0,check!$C$11+(rebarps!$A7-1)*check!$I$7) -> 0
A8: 6 | B8: =IF($A8>check!$C$7,0,check!$C$11+(rebarps!$A8-1)*check!$I$7) -> 0
A9: 7 | B9: =IF($A9>check!$C$7,0,check!$C$11+(rebarps!$A9-1)*check!$I$7) -> 0
A10: 8 | B10: =IF($A10>check!$C$7,0,check!$C$11+(rebarps!$A10-1)*check!$I$7) -> 0
A11: 9 | B11: =IF($A11>check!$C$7,0,check!$C$11+(rebarps!$A11-1)*check!$I$7) -> 0
A12: 10 | B12: =IF($A12>check!$C$7,0,check!$C$11+(rebarps!$A12-1)*check!$I$7) -> 0
A13: 11 | B13: =IF($A13>check!$C$7,0,check!$C$11+(rebarps!$A13-1)*check!$I$7) -> 0
A14: 12 | B14: =IF($A14>check!$C$7,0,check!$C$11+(rebarps!$A14-1)*check!$I$7) -> 0
A15: 13 | B15: =IF($A15>check!$C$7,0,check!$C$11+(rebarps!$A15-1)*check!$I$7) -> 0
A16: 14 | B16: =IF($A16>check!$C$7,0,check!$C$11+(rebarps!$A16-1)*check!$I$7) -> 0
A17: 15 | B17: =IF($A17>check!$C$7,0,check!$C$11+(rebarps!$A17-1)*check!$I$7) -> 0
A18: 16 | B18: =IF($A18>check!$C$7,0,check!$C$11+(rebarps!$A18-1)*check!$I$7) -> 0
... A22: 20 | B22: =IF($A22>check!$C$7,0,check!$C$11+(rebarps!$A22-1)*check!$I$7) -> 0

Sheet rectangle
A1: 矩形作圖 | B1: 柱寬= | C1: =check!C3 -> 50 | D1: cm | E1: 柱深= | F1: =check!C4 -> 40 | G1: cm
A2: No | B2: x | C2: y
A3: 0 | B3: =R0!B15 -> -25 | C3: =R0!C15 -> 20
A4: 1 | B4: =R0!B16 -> 25 | C4: =R0!C16 -> 20
A5: 2 | B5: =R0!B17 -> 25 | C5: =R0!C17 -> -20
A6: 3 | B6: =R0!B18 -> -25 | C6: =R0!C18 -> -20
A7: 4 | B7: =B3 -> -25 | C7: =C3 -> 20

Sheet bar
B1: 鋼筋支數n= | C1: =COUNTIF(G3:G402,">0") -> 12 | D1: 支 | E1: As,sum= | F1: =SUM(H3:H402) -> 34.2 | G1: cm2 | N1: cosθ | O1: sinθ
A2: NOX | B2: NOY | C2: x | D2: y | E2: x_rot | F2: y_rot | G2: rebar no | H2: rebar As | J2: 鋼筋 | N2: =R0!H7 -> 6.1257423e-17 | O2: =R0!I7 -> 1
A3: =INT((ROW(A2)-2)/20)+1 -> 1 | B3: =MOD(ROW(B2)-2,20)+1 -> 1 | C3: {=IF(G3=0,C$3,check!$C$3/2-INDEX(rebarps!$B$2:$V$22,1,B3+1))} -> 19 | D3: {=IF(G3=0,D$3,check!$C$4/2-INDEX(rebarps!$B$2:$V$22,A3+1,1))} -> 14 | E3: =(C3)*$N$2 - (D3)*$O$2 -> -14 | F3: =(C3)*$O$2 + (D3)*$N$2 -> 19 | G3: {=INDEX(rebarps!$C$3:$V$22,A3,B3)} -> 6 | H3: =IF(G3>0,LOOKUP(G3,J$4:J$12,K$4:K$12),0) -> 2.85 | J3: 號數 | K3: 面積 | L3: 直徑(cm)
A4: =INT((ROW(A3)-2)/20)+1 -> 1 | B4: =MOD(ROW(B3)-2,20)+1 -> 2 | C4: {=IF(G4=0,C$3,check!$C$3/2-INDEX(rebarps!$B$2:$V$22,1,B4+1))} -> 6.3333333 | D4: {=IF(G4=0,D$3,check!$C$4/2-INDEX(rebarps!$B$2:$V$22,A4+1,1))} -> 14 | E4: =(C4)*$N$2 - (D4)*$O$2 -> -14 | F4: =(C4)*$O$2 + (D4)*$N$2 -> 6.3333333 | G4: {=INDEX(rebarps!$C$3:$V$22,A4,B4)} -> 6 | H4: =IF(G4>0,LOOKUP(G4,J$4:J$12,K$4:K$12),0) -> 2.85 | J4: 3 | K4: 0.71 | L4: 0.953
A5: =INT((ROW(A4)-2)/20)+1 -> 1 | B5: =MOD(ROW(B4)-2,20)+1 -> 3 | C5: {=IF(G5=0,C$3,check!$C$3/2-INDEX(rebarps!$B$2:$V$22,1,B5+1))} -> -6.3333333 | D5: {=IF(G5=0,D$3,check!$C$4/2-INDEX(rebarps!$B$2:$V$22,A5+1,1))} -> 14 | E5: =(C5)*$N$2 - (D5)*$O$2 -> -14 | F5: =(C5)*$O$2 + (D5)*$N$2 -> -6.3333333 | G5: {=INDEX(rebarps!$C$3:$V$22,A5,B5)} -> 6 | H5: =IF(G5>0,LOOKUP(G5,J$4:J$12,K$4:K$12),0) -> 2.85 | J5: 4 | K5: 1.27 | L5: 1.27
A6: =INT((ROW(A5)-2)/20)+1 -> 1 | B6: =MOD(ROW(B5)-2,20)+1 -> 4 | C6: {=IF(G6=0,C$3,check!$C$3/2-INDEX(rebarps!$B$2:$V$22,1,B6+1))} -> -19 | D6: {=IF(G6=0,D$3,check!$C$4/2-INDEX(rebarps!$B$2:$V$22,A6+1,1))} -> 14 | E6: =(C6)*$N$2 - (D6)*$O$2 -> -14 | F6: =(C6)*$O$2 + (D6)*$N$2 -> -19 | G6: {=INDEX(rebarps!$C$3:$V$22,A6,B6)} -> 6 | H6: =IF(G6>0,LOOKUP(G6,J$4:J$12,K$4:K$12),0) -> 2.85 | J6: 5 | K6: 1.98 | L6: 15.9
A7: =INT((ROW(A6)-2)/20)+1 -> 1 | B7: =MOD(ROW(B6)-2,20)+1 -> 5 | C7: {=IF(G7=0,C$3,check!$C$3/2-INDEX(rebarps!$B$2:$V$22,1,B7+1))} -> 19 | D7: {=IF(G7=0,D$3,check!$C$4/2-INDEX(rebarps!$B$2:$V$22,A7+1,1))} -> 14 | E7: =(C7)*$N$2 - (D7)*$O$2 -> -14 | F7: =(C7)*$O$2 + (D7)*$N$2 -> 19 | G7: {=INDEX(rebarps!$C$3:$V$22,A7,B7)} -> 0 | H7: =IF(G7>0,LOOKUP(G7,J$4:J$12,K$4:K$12),0) -> 0 | J7: 6 | K7: 2.85 | L7: 1.91
A8: =INT((ROW(A7)-2)/20)+1 -> 1 | B8: =MOD(ROW(B7)-2,20)+1 -> 6 | C8: {=IF(G8=0,C$3,check!$C$3/2-INDEX(rebarps!$B$2:$V$22,1,B8+1))} -> 19 | D8: {=IF(G8=0,D$3,check!$C$4/2-INDEX(rebarps!$B$2:$V$22,A8+1,1))} -> 14 | E8: =(C8)*$N$2 - (D8)*$O$2 -> -14 | F8: =(C8)*$O$2 + (D8)*$N$2 -> 19 | G8: {=INDEX(rebarps!$C$3:$V$22,A8,B8)} -> 0 | H8: =IF(G8>0,LOOKUP(G8,J$4:J$12,K$4:K$12),0) -> 0 | J8: 7 | K8: 3.87 | L8: 2.22
A9: =INT((ROW(A8)-2)/20)+1 -> 1 | B9: =MOD(ROW(B8)-2,20)+1 -> 7 | C9: {=IF(G9=0,C$3,check!$C$3/2-INDEX(rebarps!$B$2:$V$22,1,B9+1))} -> 19 | D9: {=IF(G9=0,D$3,check!$C$4/2-INDEX(rebarps!$B$2:$V$22,A9+1,1))} -> 14 | E9: =(C9)*$N$2 - (D9)*$O$2 -> -14 | F9: =(C9)*$O$2 + (D9)*$N$2 -> 19 | G9: {=INDEX(rebarps!$C$3:$V$22,A9,B9)} -> 0 | H9: =IF(G9>0,LOOKUP(G9,J$4:J$12,K$4:K$12),0) -> 0 | J9: 8 | K9: 5.07 | L9: 2.54
A10: =INT((ROW(A9)-2)/20)+1 -> 1 | B10: =MOD(ROW(B9)-2,20)+1 -> 8 | C10: {=IF(G10=0,C$3,check!$C$3/2-INDEX(rebarps!$B$2:$V$22,1,B10+1))} -> 19 | D10: {=IF(G10=0,D$3,check!$C$4/2-INDEX(rebarps!$B$2:$V$22,A10+1,1))} -> 14 | E10: =(C10)*$N$2 - (D10)*$O$2 -> -14 | F10: =(C10)*$O$2 + (D10)*$N$2 -> 19 | G10: {=INDEX(rebarps!$C$3:$V$22,A10,B10)} -> 0 | H10: =IF(G10>0,LOOKUP(G10,J$4:J$12,K$4:K$12),0) -> 0 | J10: 9 | K10: 6.45 | L10: 2.87
A11: =INT((ROW(A10)-2)/20)+1 -> 1 | B11: =MOD(ROW(B10)-2,20)+1 -> 9 | C11: {=IF(G11=0,C$3,check!$C$3/2-INDEX(rebarps!$B$2:$V$22,1,B11+1))} -> 19 | D11: {=IF(G11=0,D$3,check!$C$4/2-INDEX(rebarps!$B$2:$V$22,A11+1,1))} -> 14 | E11: =(C11)*$N$2 - (D11)*$O$2 -> -14 | F11: =(C11)*$O$2 + (D11)*$N$2 -> 19 | G11: {=INDEX(rebarps!$C$3:$V$22,A11,B11)} -> 0 | H11: =IF(G11>0,LOOKUP(G11,J$4:J$12,K$4:K$12),0) -> 0 | J11: 10 | K11: 8.17 | L11: 3.22
A12: =INT((ROW(A11)-2)/20)+1 -> 1 | B12: =MOD(ROW(B11)-2,20)+1 -> 10 | C12: {=IF(G12=0,C$3,check!$C$3/2-INDEX(rebarps!$B$2:$V$22,1,B12+1))} -> 19 | D12: {=IF(G12=0,D$3,check!$C$4/2-INDEX(rebarps!$B$2:$V$22,A12+1,1))} -> 14 | E12: =(C12)*$N$2 - (D12)*$O$2 -> -14 | F12: =(C12)*$O$2 + (D12)*$N$2 -> 19 | G12: {=INDEX(rebarps!$C$3:$V$22,A12,B12)} -> 0 | H12: =IF(G12>0,LOOKUP(G12,J$4:J$12,K$4:K$12),0) -> 0 | J12: 11 | K12: 10.01 | L12: 3.58
A13: =INT((ROW(A12)-2)/20)+1 -> 1 | B13: =MOD(ROW(B12)-2,20)+1 -> 11 | C13: {=IF(G13=0,C$3,check!$C$3/2-INDEX(rebarps!$B$2:$V$22,1,B13+1))} -> 19 | D13: {=IF(G13=0,D$3,check!$C$4/2-INDEX(rebarps!$B$2:$V$22,A13+1,1))} -> 14 | E13: =(C13)*$N$2 - (D13)*$O$2 -> -14 | F13: =(C13)*$O$2 + (D13)*$N$2 -> 19 | G13: {=INDEX(rebarps!$C$3:$V$22,A13,B13)} -> 0 | H13: =IF(G13>0,LOOKUP(G13,J$4:J$12,K$4:K$12),0) -> 0
A14: =INT((ROW(A13)-2)/20)+1 -> 1 | B14: =MOD(ROW(B13)-2,20)+1 -> 12 | C14: {=IF(G14=0,C$3,check!$C$3/2-INDEX(rebarps!$B$2:$V$22,1,B14+1))} -> 19 | D14: {=IF(G14=0,D$3,check!$C$4/2-INDEX(rebarps!$B$2:$V$22,A14+1,1))} -> 14 | E14: =(C14)*$N$2 - (D14)*$O$2 -> -14 | F14: =(C14)*$O$2 + (D14)*$N$2 -> 19 | G14: {=INDEX(rebarps!$C$3:$V$22,A14,B14)} -> 0 | H14: =IF(G14>0,LOOKUP(G14,J$4:J$12,K$4:K$12),0) -> 0
A15: =INT((ROW(A14)-2)/20)+1 -> 1 | B15: =MOD(ROW(B14)-2,20)+1 -> 13 | C15: {=IF(G15=0,C$3,check!$C$3/2-INDEX(rebarps!$B$2:$V$22,1,B15+1))} -> 19 | D15: {=IF(G15=0,D$3,check!$C$4/2-INDEX(rebarps!$B$2:$V$22,A15+1,1))} -> 14 | E15: =(C15)*$N$2 - (D15)*$O$2 -> -14 | F15: =(C15)*$O$2 + (D15)*$N$2 -> 19 | G15: {=INDEX(rebarps!$C$3:$V$22,A15,B15)} -> 0 | H15: =IF(G15>0,LOOKUP(G15,J$4:J$12,K$4:K$12),0) -> 0
A16: =INT((ROW(A15)-2)/20)+1 -> 1 | B16: =MOD(ROW(B15)-2,20)+1 -> 14 | C16: {=IF(G16=0,C$3,check!$C$3/2-INDEX(rebarps!$B$2:$V$22,1,B16+1))} -> 19 | D16: {=IF(G16=0,D$3,check!$C$4/2-INDEX(rebarps!$B$2:$V$22,A16+1,1))} -> 14 | E16: =(C16)*$N$2 - (D16)*$O$2 -> -14 | F16: =(C16)*$O$2 + (D16)*$N$2 -> 19 | G16: {=INDEX(rebarps!$C$3:$V$22,A16,B16)} -> 0 | H16: =IF(G16>0,LOOKUP(G16,J$4:J$12,K$4:K$12),0) -> 0
A17: =INT((ROW(A16)-2)/20)+1 -> 1 | B17: =MOD(ROW(B16)-2,20)+1 -> 15 | C17: {=IF(G17=0,C$3,check!$C$3/2-INDEX(rebarps!$B$2:$V$22,1,B17+1))} -> 19 | D17: {=IF(G17=0,D$3,check!$C$4/2-INDEX(rebarps!$B$2:$V$22,A17+1,1))} -> 14 | E17: =(C17)*$N$2 - (D17)*$O$2 -> -14 | F17: =(C17)*$O$2 + (D17)*$N$2 -> 19 | G17: {=INDEX(rebarps!$C$3:$V$22,A17,B17)} -> 0 | H17: =IF(G17>0,LOOKUP(G17,J$4:J$12,K$4:K$12),0) -> 0
A18: =INT((ROW(A17)-2)/20)+1 -> 1 | B18: =MOD(ROW(B17)-2,20)+1 -> 16 | C18: {=IF(G18=0,C$3,check!$C$3/2-INDEX(rebarps!$B$2:$V$22,1,B18+1))} -> 19 | D18: {=IF(G18=0,D$3,check!$C$4/2-INDEX(rebarps!$B$2:$V$22,A18+1,1))} -> 14 | E18: =(C18)*$N$2 - (D18)*$O$2 -> -14 | F18: =(C18)*$O$2 + (D18)*$N$2 -> 19 | G18: {=INDEX(rebarps!$C$3:$V$22,A18,B18)} -> 0 | H18: =IF(G18>0,LOOKUP(G18,J$4:J$12,K$4:K$12),0) -> 0
A19: =INT((ROW(A18)-2)/20)+1 -> 1 | B19: =MOD(ROW(B18)-2,20)+1 -> 17 | C19: {=IF(G19=0,C$3,check!$C$3/2-INDEX(rebarps!$B$2:$V$22,1,B19+1))} -> 19 | D19: {=IF(G19=0,D$3,check!$C$4/2-INDEX(rebarps!$B$2:$V$22,A19+1,1))} -> 14 | E19: =(C19)*$N$2 - (D19)*$O$2 -> -14 | F19: =(C19)*$O$2 + (D19)*$N$2 -> 19 | G19: {=INDEX(rebarps!$C$3:$V$22,A19,B19)} -> 0 | H19: =IF(G19>0,LOOKUP(G19,J$4:J$12,K$4:K$12),0) -> 0
A20: =INT((ROW(A19)-2)/20)+1 -> 1 | B20: =MOD(ROW(B19)-2,20)+1 -> 18 | C20: {=IF(G20=0,C$3,check!$C$3/2-INDEX(rebarps!$B$2:$V$22,1,B20+1))} -> 19 | D20: {=IF(G20=0,D$3,check!$C$4/2-INDEX(rebarps!$B$2:$V$22,A20+1,1))} -> 14 | E20: =(C20)*$N$2 - (D20)*$O$2 -> -14 | F20: =(C20)*$O$2 + (D20)*$N$2 -> 19 | G20: {=INDEX(rebarps!$C$3:$V$22,A20,B20)} -> 0 | H20: =IF(G20>0,LOOKUP(G20,J$4:J$12,K$4:K$12),0) -> 0
A21: =INT((ROW(A20)-2)/20)+1 -> 1 | B21: =MOD(ROW(B20)-2,20)+1 -> 19 | C21: {=IF(G21=0,C$3,check!$C$3/2-INDEX(rebarps!$B$2:$V$22,1,B21+1))} -> 19 | D21: {=IF(G21=0,D$3,check!$C$4/2-INDEX(rebarps!$B$2:$V$22,A21+1,1))} -> 14 | E21: =(C21)*$N$2 - (D21)*$O$2 -> -14 | F21: =(C21)*$O$2 + (D21)*$N$2 -> 19 | G21: {=INDEX(rebarps!$C$3:$V$22,A21,B21)} -> 0 | H21: =IF(G21>0,LOOKUP(G21,J$4:J$12,K$4:K$12),0) -> 0
A22: =INT((ROW(A21)-2)/20)+1 -> 1 | B22: =MOD(ROW(B21)-2,20)+1 -> 20 | C22: {=IF(G22=0,C$3,check!$C$3/2-INDEX(rebarps!$B$2:$V$22,1,B22+1))} -> 19 | D22: {=IF(G22=0,D$3,check!$C$4/2-INDEX(rebarps!$B$2:$V$22,A22+1,1))} -> 14 | E22: =(C22)*$N$2 - (D22)*$O$2 -> -14 | F22: =(C22)*$O$2 + (D22)*$N$2 -> 19 | G22: {=INDEX(rebarps!$C$3:$V$22,A22,B22)} -> 0 | H22: =IF(G22>0,LOOKUP(G22,J$4:J$12,K$4:K$12),0) -> 0
A23: =INT((ROW(A22)-2)/20)+1 -> 2 | B23: =MOD(ROW(B22)-2,20)+1 -> 1 | C23: {=IF(G23=0,C$3,check!$C$3/2-INDEX(rebarps!$B$2:$V$22,1,B23+1))} -> 19 | D23: {=IF(G23=0,D$3,check!$C$4/2-INDEX(rebarps!$B$2:$V$22,A23+1,1))} -> 4.6666667 | E23: =(C23)*$N$2 - (D23)*$O$2 -> -4.6666667 | F23: =(C23)*$O$2 + (D23)*$N$2 -> 19 | G23: {=INDEX(rebarps!$C$3:$V$22,A23,B23)} -> 6 | H23: =IF(G23>0,LOOKUP(G23,J$4:J$12,K$4:K$12),0) -> 2.85
A24: =INT((ROW(A23)-2)/20)+1 -> 2 | B24: =MOD(ROW(B23)-2,20)+1 -> 2 | C24: {=IF(G24=0,C$3,check!$C$3/2-INDEX(rebarps!$B$2:$V$22,1,B24+1))} -> 19 | D24: {=IF(G24=0,D$3,check!$C$4/2-INDEX(rebarps!$B$2:$V$22,A24+1,1))} -> 14 | E24: =(C24)*$N$2 - (D24)*$O$2 -> -14 | F24: =(C24)*$O$2 + (D24)*$N$2 -> 19 | G24: {=INDEX(rebarps!$C$3:$V$22,A24,B24)} -> 0 | H24: =IF(G24>0,LOOKUP(G24,J$4:J$12,K$4:K$12),0) -> 0
... A402: =INT((ROW(A401)-2)/20)+1 -> 20 | B402: =MOD(ROW(B401)-2,20)+1 -> 20 | C402: {=IF(G402=0,C$3,check!$C$3/2-INDEX(rebarps!$B$2:$V$22,1,B402+1))} -> 19 | D402: {=IF(G402=0,D$3,check!$C$4/2-INDEX(rebarps!$B$2:$V$22,A402+1,1))} -> 14 | E402: =(C402)*$N$2 - (D402)*$O$2 -> -14 | F402: =(C402)*$O$2 + (D402)*$N$2 -> 19 | G402: {=INDEX(rebarps!$C$3:$V$22,A402,B402)} -> 0 | H402: =IF(G402>0,LOOKUP(G402,J$4:J$12,K$4:K$12),0) -> 0

Sheet R0
A1: Rotated Rectangle + Horizontal Cut (No VBA) | D1: 0 | E1: /20
A2: Cut position λ (0→y_min, 1→y_max) | B2: =D1/20 -> 0 | D2: β1= | E2: =check!G5 -> 0.85
A3: Input unit | B3: cm | D3: Output unit | E3: cm
A4: Width B (input unit) | B4: =check!C3 -> 50
A5: Deepth D (input unit) | B5: =check!C4 -> 40
A6: Rotate rectangle θ (deg, about origin) | B6: =90+check!C13 -> 90 | H6: cosθ | I6: sinθ
A7: Cut position 1-(1-λ)β1 | B7: =IF(B2=0,0,1-(1-B2)*E2) -> 0 | D7: Keep side | E7: Above (y >= y_cut) | H7: =COS(RADIANS($B$6)) -> 6.1257423e-17 | I7: =SIN(RADIANS($B$6)) -> 1
A9: Unit scales (mm per unit)
A10: s_in | B10: =IF($B$3="mm",1,IF($B$3="cm",10,IF($B$3="m",1000,1))) -> 10
A11: s_out | B11: =IF($E$3="mm",1,IF($E$3="cm",10,IF($E$3="m",1000,1))) -> 10
A12: len_in_to_out | B12: =$B$10/$B$11 -> 1
A13: Rotated rectangle vertices (after rotation θ)
A14: Corner | B14: x0 | C14: y0 | D14: x_rot | E14: y_rot | F14: Inside?
A15: 1 | B15: =IF(A15=1,-$B$4/2,IF(A15=2,$B$4/2,IF(A15=3,$B$4/2,-$B$4/2))) -> -25 | C15: =IF(A15=1,$B$5/2,IF(A15=2,$B$5/2,IF(A15=3,-$B$5/2,-$B$5/2))) -> 20 | D15: =(B15)*$H$7 - (C15)*$I$7 -> -20 | E15: =(B15)*$I$7 + (C15)*$H$7 -> -25 | F15: =IF($E$7="Above (y >= y_cut)",E15>=$B$20,E15<=$B$20) -> TRUE
A16: 2 | B16: =IF(A16=1,-$B$4/2,IF(A16=2,$B$4/2,IF(A16=3,$B$4/2,-$B$4/2))) -> 25 | C16: =IF(A16=1,$B$5/2,IF(A16=2,$B$5/2,IF(A16=3,-$B$5/2,-$B$5/2))) -> 20 | D16: =(B16)*$H$7 - (C16)*$I$7 -> -20 | E16: =(B16)*$I$7 + (C16)*$H$7 -> 25 | F16: =IF($E$7="Above (y >= y_cut)",E16>=$B$20,E16<=$B$20) -> TRUE
A17: 3 | B17: =IF(A17=1,-$B$4/2,IF(A17=2,$B$4/2,IF(A17=3,$B$4/2,-$B$4/2))) -> 25 | C17: =IF(A17=1,$B$5/2,IF(A17=2,$B$5/2,IF(A17=3,-$B$5/2,-$B$5/2))) -> -20 | D17: =(B17)*$H$7 - (C17)*$I$7 -> 20 | E17: =(B17)*$I$7 + (C17)*$H$7 -> 25 | F17: =IF($E$7="Above (y >= y_cut)",E17>=$B$20,E17<=$B$20) -> TRUE
A18: 4 | B18: =IF(A18=1,-$B$4/2,IF(A18=2,$B$4/2,IF(A18=3,$B$4/2,-$B$4/2))) -> -25 | C18: =IF(A18=1,$B$5/2,IF(A18=2,$B$5/2,IF(A18=3,-$B$5/2,-$B$5/2))) -> -20 | D18: =(B18)*$H$7 - (C18)*$I$7 -> 20 | E18: =(B18)*$I$7 + (C18)*$H$7 -> -25 | F18: =IF($E$7="Above (y >= y_cut)",E18>=$B$20,E18<=$B$20) -> TRUE
G19: x | H19: y | I19: L
A20: y_cut (input unit) | B20: =$B$21 + $B$7*($D$21-$B$21) -> -25 | C20: y_cut (output unit) | D20: =$B$20*$B$12 -> -25 | E20: Nature ax= | F20: =$B$21 + $B$2*($D$21-$B$21) -> -25 | G20: =MIN(D15:D18) -> -20 | H20: =F20 -> -25 | I20: =D21-F20 -> 50
A21: y_min (input unit) | B21: =MIN($E$15:$E$18) -> -25 | C21: y_max (input unit) | D21: =MAX($E$15:$E$18) -> 25 | G21: =MAX(D15:D18) -> 20 | H21: =F20 -> -25
A23: Clipping edges (Sutherland–Hodgman for y >=/<= y_cut)
A24: Edge | B24: S idx | C24: E idx | D24: xS | E24: yS | F24: xE | G24: yE | H24: inS | I24: inE | J24: xInt | K24: nOut | L24: posStart | M24: xOut1 | N24: yOut1 | O24: xOut2 | P24: yOut2
A25: 1 | B25: 1 | C25: 2 | D25: =INDEX($D$15:$D$18,B25) -> -20 | E25: =INDEX($E$15:$E$18,B25) -> -25 | F25: =INDEX($D$15:$D$18,C25) -> -20 | G25: =INDEX($E$15:$E$18,C25) -> 25 | H25: =IF($E$7="Above (y >= y_cut)",E25>=$B$20,E25<=$B$20) -> TRUE | I25: =IF($E$7="Above (y >= y_cut)",G25>=$B$20,G25<=$B$20) -> TRUE | J25: =IF(H25<>I25,IF(G25=E25,"",D25 + ($B$20-E25)*(F25-D25)/(G25-E25)),"") | K25: =IF(H25,1,IF(I25,2,0)) -> 1 | L25: 1 | M25: =IF(K25=0,"",IF(H25,IF(I25,F25,J25),J25)) -> -20 | N25: =IF(K25=0,"",IF(H25,IF(I25,G25,$B$20),$B$20)) -> 25 | O25: =IF(K25<2,"",F25) | P25: =IF(K25<2,"",G25)
A26: 2 | B26: 2 | C26: 3 | D26: =INDEX($D$15:$D$18,B26) -> -20 | E26: =INDEX($E$15:$E$18,B26) -> 25 | F26: =INDEX($D$15:$D$18,C26) -> 20 | G26: =INDEX($E$15:$E$18,C26) -> 25 | H26: =IF($E$7="Above (y >= y_cut)",E26>=$B$20,E26<=$B$20) -> TRUE | I26: =IF($E$7="Above (y >= y_cut)",G26>=$B$20,G26<=$B$20) -> TRUE | J26: =IF(H26<>I26,IF(G26=E26,"",D26 + ($B$20-E26)*(F26-D26)/(G26-E26)),"") | K26: =IF(H26,1,IF(I26,2,0)) -> 1 | L26: =L25+K25 -> 2 | M26: =IF(K26=0,"",IF(H26,IF(I26,F26,J26),J26)) -> 20 | N26: =IF(K26=0,"",IF(H26,IF(I26,G26,$B$20),$B$20)) -> 25 | O26: =IF(K26<2,"",F26) | P26: =IF(K26<2,"",G26)
A27: 3 | B27: 3 | C27: 4 | D27: =INDEX($D$15:$D$18,B27) -> 20 | E27: =INDEX($E$15:$E$18,B27) -> 25 | F27: =INDEX($D$15:$D$18,C27) -> 20 | G27: =INDEX($E$15:$E$18,C27) -> -25 | H27: =IF($E$7="Above (y >= y_cut)",E27>=$B$20,E27<=$B$20) -> TRUE | I27: =IF($E$7="Above (y >= y_cut)",G27>=$B$20,G27<=$B$20) -> TRUE | J27: =IF(H27<>I27,IF(G27=E27,"",D27 + ($B$20-E27)*(F27-D27)/(G27-E27)),"") | K27: =IF(H27,1,IF(I27,2,0)) -> 1 | L27: =L26+K26 -> 3 | M27: =IF(K27=0,"",IF(H27,IF(I27,F27,J27),J27)) -> 20 | N27: =IF(K27=0,"",IF(H27,IF(I27,G27,$B$20),$B$20)) -> -25 | O27: =IF(K27<2,"",F27) | P27: =IF(K27<2,"",G27)
A28: 4 | B28: 4 | C28: 1 | D28: =INDEX($D$15:$D$18,B28) -> 20 | E28: =INDEX($E$15:$E$18,B28) -> -25 | F28: =INDEX($D$15:$D$18,C28) -> -20 | G28: =INDEX($E$15:$E$18,C28) -> -25 | H28: =IF($E$7="Above (y >= y_cut)",E28>=$B$20,E28<=$B$20) -> TRUE | I28: =IF($E$7="Above (y >= y_cut)",G28>=$B$20,G28<=$B$20) -> TRUE | J28: =IF(H28<>I28,IF(G28=E28,"",D28 + ($B$20-E28)*(F28-D28)/(G28-E28)),"") | K28: =IF(H28,1,IF(I28,2,0)) -> 1 | L28: =L27+K27 -> 4 | M28: =IF(K28=0,"",IF(H28,IF(I28,F28,J28),J28)) -> -20 | N28: =IF(K28=0,"",IF(H28,IF(I28,G28,$B$20),$B$20)) -> -25 | O28: =IF(K28<2,"",F28) | P28: =IF(K28<2,"",G28)
A29: CLOSE | D29: =D25 -> -20 | E29: =E25 -> -25
A30: Total vertices N_out | B30: =SUM($K$25:$K$28) -> 4
A32: Clipped polygon vertices (in traversal order)
A33: k | B33: x_out (in) | C33: y_out (in) | D33: x_out (out) | E33: y_out (out) | F33: Δ | G33: x_term | H33: y_term
A34: 1 | B34: =IF($A34>$B$30,NA(),IF(K34=1,INDEX($M$25:$M$28,J34),INDEX($O$25:$O$28,J34))) -> -20 | C34: =IF($A34>$B$30,NA(),IF(K34=1,INDEX($N$25:$N$28,J34),INDEX($P$25:$P$28,J34))) -> 25 | D34: =IF(ISNA(B34),NA(),B34*$B$12) -> -20 | E34: =IF(ISNA(C34),NA(),C34*$B$12) -> 25 | F34: =IF($A34>$B$30,"",B34*M34-L34*C34) -> -1000 | G34: =IF($A34>$B$30,"",(B34+L34)*F34) -> 0 | H34: =IF($A34>$B$30,"",(C34+M34)*F34) -> -50000 | I34: =IF($A34>$B$30,"",LOOKUP($A34,$L$25:$L$28,$A$25:$A$28)) -> 1 | J34: =IF($A34>$B$30,"",MATCH(I34,$A$25:$A$28,0)) -> 1 | K34: =IF($A34>$B$30,"",$A34-INDEX($L$25:$L$28,J34)+1) -> 1 | L34: =IF($A34>$B$30,"",IF($A34<$B$30,B35,$B$34)) -> 20 | M34: =IF($A34>$B$30,"",IF($A34<$B$30,C35,$C$34)) -> 25
A35: 2 | B35: =IF($A35>$B$30,NA(),IF(K35=1,INDEX($M$25:$M$28,J35),INDEX($O$25:$O$28,J35))) -> 20 | C35: =IF($A35>$B$30,NA(),IF(K35=1,INDEX($N$25:$N$28,J35),INDEX($P$25:$P$28,J35))) -> 25 | D35: =IF(ISNA(B35),NA(),B35*$B$12) -> 20 | E35: =IF(ISNA(C35),NA(),C35*$B$12) -> 25 | F35: =IF($A35>$B$30,"",B35*M35-L35*C35) -> -1000 | G35: =IF($A35>$B$30,"",(B35+L35)*F35) -> -40000 | H35: =IF($A35>$B$30,"",(C35+M35)*F35) -> 0 | I35: =IF($A35>$B$30,"",LOOKUP($A35,$L$25:$L$28,$A$25:$A$28)) -> 2 | J35: =IF($A35>$B$30,"",MATCH(I35,$A$25:$A$28,0)) -> 2 | K35: =IF($A35>$B$30,"",$A35-INDEX($L$25:$L$28,J35)+1) -> 1 | L35: =IF($A35>$B$30,"",IF($A35<$B$30,B36,$B$34)) -> 20 | M35: =IF($A35>$B$30,"",IF($A35<$B$30,C36,$C$34)) -> -25
A36: 3 | B36: =IF($A36>$B$30,NA(),IF(K36=1,INDEX($M$25:$M$28,J36),INDEX($O$25:$O$28,J36))) -> 20 | C36: =IF($A36>$B$30,NA(),IF(K36=1,INDEX($N$25:$N$28,J36),INDEX($P$25:$P$28,J36))) -> -25 | D36: =IF(ISNA(B36),NA(),B36*$B$12) -> 20 | E36: =IF(ISNA(C36),NA(),C36*$B$12) -> -25 | F36: =IF($A36>$B$30,"",B36*M36-L36*C36) -> -1000 | G36: =IF($A36>$B$30,"",(B36+L36)*F36) -> 0 | H36: =IF($A36>$B$30,"",(C36+M36)*F36) -> 50000 | I36: =IF($A36>$B$30,"",LOOKUP($A36,$L$25:$L$28,$A$25:$A$28)) -> 3 | J36: =IF($A36>$B$30,"",MATCH(I36,$A$25:$A$28,0)) -> 3 | K36: =IF($A36>$B$30,"",$A36-INDEX($L$25:$L$28,J36)+1) -> 1 | L36: =IF($A36>$B$30,"",IF($A36<$B$30,B37,$B$34)) -> -20 | M36: =IF($A36>$B$30,"",IF($A36<$B$30,C37,$C$34)) -> -25
A37: 4 | B37: =IF($A37>$B$30,NA(),IF(K37=1,INDEX($M$25:$M$28,J37),INDEX($O$25:$O$28,J37))) -> -20 | C37: =IF($A37>$B$30,NA(),IF(K37=1,INDEX($N$25:$N$28,J37),INDEX($P$25:$P$28,J37))) -> -25 | D37: =IF(ISNA(B37),NA(),B37*$B$12) -> -20 | E37: =IF(ISNA(C37),NA(),C37*$B$12) -> -25 | F37: =IF($A37>$B$30,"",B37*M37-L37*C37) -> -1000 | G37: =IF($A37>$B$30,"",(B37+L37)*F37) -> 40000 | H37: =IF($A37>$B$30,"",(C37+M37)*F37) -> 0 | I37: =IF($A37>$B$30,"",LOOKUP($A37,$L$25:$L$28,$A$25:$A$28)) -> 4 | J37: =IF($A37>$B$30,"",MATCH(I37,$A$25:$A$28,0)) -> 4 | K37: =IF($A37>$B$30,"",$A37-INDEX($L$25:$L$28,J37)+1) -> 1 | L37: =IF($A37>$B$30,"",IF($A37<$B$30,B38,$B$34)) -> -20 | M37: =IF($A37>$B$30,"",IF($A37<$B$30,C38,$C$34)) -> 25
A38: 5 | B38: =IF($A38>$B$30,NA(),IF(K38=1,INDEX($M$25:$M$28,J38),INDEX($O$25:$O$28,J38))) -> #N/A | C38: =IF($A38>$B$30,NA(),IF(K38=1,INDEX($N$25:$N$28,J38),INDEX($P$25:$P$28,J38))) -> #N/A | D38: =IF(ISNA(B38),NA(),B38*$B$12) -> #N/A | E38: =IF(ISNA(C38),NA(),C38*$B$12) -> #N/A | F38: =IF($A38>$B$30,"",B38*M38-L38*C38) | G38: =IF($A38>$B$30,"",(B38+L38)*F38) | H38: =IF($A38>$B$30,"",(C38+M38)*F38) | I38: =IF($A38>$B$30,"",LOOKUP($A38,$L$25:$L$28,$A$25:$A$28)) | J38: =IF($A38>$B$30,"",MATCH(I38,$A$25:$A$28,0)) | K38: =IF($A38>$B$30,"",$A38-INDEX($L$25:$L$28,J38)+1) | L38: =IF($A38>$B$30,"",IF($A38<$B$30,B39,$B$34)) | M38: =IF($A38>$B$30,"",IF($A38<$B$30,C39,$C$34))
A39: 6 | B39: =IF($A39>$B$30,NA(),IF(K39=1,INDEX($M$25:$M$28,J39),INDEX($O$25:$O$28,J39))) -> #N/A | C39: =IF($A39>$B$30,NA(),IF(K39=1,INDEX($N$25:$N$28,J39),INDEX($P$25:$P$28,J39))) -> #N/A | D39: =IF(ISNA(B39),NA(),B39*$B$12) -> #N/A | E39: =IF(ISNA(C39),NA(),C39*$B$12) -> #N/A | F39: =IF($A39>$B$30,"",B39*M39-L39*C39) | G39: =IF($A39>$B$30,"",(B39+L39)*F39) | H39: =IF($A39>$B$30,"",(C39+M39)*F39) | I39: =IF($A39>$B$30,"",LOOKUP($A39,$L$25:$L$28,$A$25:$A$28)) | J39: =IF($A39>$B$30,"",MATCH(I39,$A$25:$A$28,0)) | K39: =IF($A39>$B$30,"",$A39-INDEX($L$25:$L$28,J39)+1) | L39: =IF($A39>$B$30,"",IF($A39<$B$30,B40,$B$34)) | M39: =IF($A39>$B$30,"",IF($A39<$B$30,C40,$C$34))
A40: 7 | B40: =IF($A40>$B$30,NA(),IF(K40=1,INDEX($M$25:$M$28,J40),INDEX($O$25:$O$28,J40))) -> #N/A | C40: =IF($A40>$B$30,NA(),IF(K40=1,INDEX($N$25:$N$28,J40),INDEX($P$25:$P$28,J40))) -> #N/A | D40: =IF(ISNA(B40),NA(),B40*$B$12) -> #N/A | E40: =IF(ISNA(C40),NA(),C40*$B$12) -> #N/A | F40: =IF($A40>$B$30,"",B40*M40-L40*C40) | G40: =IF($A40>$B$30,"",(B40+L40)*F40) | H40: =IF($A40>$B$30,"",(C40+M40)*F40) | I40: =IF($A40>$B$30,"",LOOKUP($A40,$L$25:$L$28,$A$25:$A$28)) | J40: =IF($A40>$B$30,"",MATCH(I40,$A$25:$A$28,0)) | K40: =IF($A40>$B$30,"",$A40-INDEX($L$25:$L$28,J40)+1) | L40: =IF($A40>$B$30,"",IF($A40<$B$30,B41,$B$34)) | M40: =IF($A40>$B$30,"",IF($A40<$B$30,C41,$C$34))
A41: 8 | B41: =IF($A41>$B$30,NA(),IF(K41=1,INDEX($M$25:$M$28,J41),INDEX($O$25:$O$28,J41))) -> #N/A | C41: =IF($A41>$B$30,NA(),IF(K41=1,INDEX($N$25:$N$28,J41),INDEX($P$25:$P$28,J41))) -> #N/A | D41: =IF(ISNA(B41),NA(),B41*$B$12) -> #N/A | E41: =IF(ISNA(C41),NA(),C41*$B$12) -> #N/A | F41: =IF($A41>$B$30,"",B41*M41-L41*C41) | G41: =IF($A41>$B$30,"",(B41+L41)*F41) | H41: =IF($A41>$B$30,"",(C41+M41)*F41) | I41: =IF($A41>$B$30,"",LOOKUP($A41,$L$25:$L$28,$A$25:$A$28)) | J41: =IF($A41>$B$30,"",MATCH(I41,$A$25:$A$28,0)) | K41: =IF($A41>$B$30,"",$A41-INDEX($L$25:$L$28,J41)+1) | L41: =IF($A41>$B$30,"",IF($A41<$B$30,B42,$B$34)) | M41: =IF($A41>$B$30,"",IF($A41<$B$30,C42,$C$34))
A42: close | B42: =IF($B$30<1,NA(),B34) -> -20 | C42: =IF($B$30<1,NA(),C34) -> 25 | D42: =IF($B$30<1,NA(),D34) -> -20 | E42: =IF($B$30<1,NA(),E34) -> 25
A44: Results
...

Sheet R1
A1: Rotated Rectangle + Horizontal Cut (No VBA) | D1: 1.9 | E1: /20
A2: Cut position λ (0→y_min, 1→y_max) | B2: =D1/20 -> 0.095 | D2: β1= | E2: =check!G5 -> 0.85
A3: Input unit | B3: cm | D3: Output unit | E3: cm
A4: Width B (input unit) | B4: =check!C3 -> 50
A5: Deepth D (input unit) | B5: =check!C4 -> 40
A6: Rotate rectangle θ (deg, about origin) | B6: =90+check!C13 -> 90 | H6: cosθ | I6: sinθ
A7: Cut position 1-(1-λ)β1 | B7: =IF(B2=0,0,1-(1-B2)*E2) -> 0.23075 | D7: Keep side | E7: Above (y >= y_cut) | H7: =COS(RADIANS($B$6)) -> 6.1257423e-17 | I7: =SIN(RADIANS($B$6)) -> 1
A9: Unit scales (mm per unit)
A10: s_in | B10: =IF($B$3="mm",1,IF($B$3="cm",10,IF($B$3="m",1000,1))) -> 10
A11: s_out | B11: =IF($E$3="mm",1,IF($E$3="cm",10,IF($E$3="m",1000,1))) -> 10
A12: len_in_to_out | B12: =$B$10/$B$11 -> 1
A13: Rotated rectangle vertices (after rotation θ)
A14: Corner | B14: x0 | C14: y0 | D14: x_rot | E14: y_rot | F14: Inside?
A15: 1 | B15: =IF(A15=1,-$B$4/2,IF(A15=2,$B$4/2,IF(A15=3,$B$4/2,-$B$4/2))) -> -25 | C15: =IF(A15=1,$B$5/2,IF(A15=2,$B$5/2,IF(A15=3,-$B$5/2,-$B$5/2))) -> 20 | D15: =(B15)*$H$7 - (C15)*$I$7 -> -20 | E15: =(B15)*$I$7 + (C15)*$H$7 -> -25 | F15: =IF($E$7="Above (y >= y_cut)",E15>=$B$20,E15<=$B$20) -> FALSE
A16: 2 | B16: =IF(A16=1,-$B$4/2,IF(A16=2,$B$4/2,IF(A16=3,$B$4/2,-$B$4/2))) -> 25 | C16: =IF(A16=1,$B$5/2,IF(A16=2,$B$5/2,IF(A16=3,-$B$5/2,-$B$5/2))) -> 20 | D16: =(B16)*$H$7 - (C16)*$I$7 -> -20 | E16: =(B16)*$I$7 + (C16)*$H$7 -> 25 | F16: =IF($E$7="Above (y >= y_cut)",E16>=$B$20,E16<=$B$20) -> TRUE
A17: 3 | B17: =IF(A17=1,-$B$4/2,IF(A17=2,$B$4/2,IF(A17=3,$B$4/2,-$B$4/2))) -> 25 | C17: =IF(A17=1,$B$5/2,IF(A17=2,$B$5/2,IF(A17=3,-$B$5/2,-$B$5/2))) -> -20 | D17: =(B17)*$H$7 - (C17)*$I$7 -> 20 | E17: =(B17)*$I$7 + (C17)*$H$7 -> 25 | F17: =IF($E$7="Above (y >= y_cut)",E17>=$B$20,E17<=$B$20) -> TRUE
A18: 4 | B18: =IF(A18=1,-$B$4/2,IF(A18=2,$B$4/2,IF(A18=3,$B$4/2,-$B$4/2))) -> -25 | C18: =IF(A18=1,$B$5/2,IF(A18=2,$B$5/2,IF(A18=3,-$B$5/2,-$B$5/2))) -> -20 | D18: =(B18)*$H$7 - (C18)*$I$7 -> 20 | E18: =(B18)*$I$7 + (C18)*$H$7 -> -25 | F18: =IF($E$7="Above (y >= y_cut)",E18>=$B$20,E18<=$B$20) -> FALSE
G19: x | H19: y | I19: L
A20: y_cut (input unit) | B20: =$B$21 + $B$7*($D$21-$B$21) -> -13.4625 | C20: y_cut (output unit) | D20: =$B$20*$B$12 -> -13.4625 | E20: Nature ax= | F20: =$B$21 + $B$2*($D$21-$B$21) -> -20.25 | G20: =MIN(D15:D18) -> -20 | H20: =F20 -> -20.25 | I20: =D21-F20 -> 45.25
A21: y_min (input unit) | B21: =MIN($E$15:$E$18) -> -25 | C21: y_max (input unit) | D21: =MAX($E$15:$E$18) -> 25 | G21: =MAX(D15:D18) -> 20 | H21: =F20 -> -20.25
A23: Clipping edges (Sutherland–Hodgman for y >=/<= y_cut)
A24: Edge | B24: S idx | C24: E idx | D24: xS | E24: yS | F24: xE | G24: yE | H24: inS | I24: inE | J24: xInt | K24: nOut | L24: posStart | M24: xOut1 | N24: yOut1 | O24: xOut2 | P24: yOut2
A25: 1 | B25: 1 | C25: 2 | D25: =INDEX($D$15:$D$18,B25) -> -20 | E25: =INDEX($E$15:$E$18,B25) -> -25 | F25: =INDEX($D$15:$D$18,C25) -> -20 | G25: =INDEX($E$15:$E$18,C25) -> 25 | H25: =IF($E$7="Above (y >= y_cut)",E25>=$B$20,E25<=$B$20) -> FALSE | I25: =IF($E$7="Above (y >= y_cut)",G25>=$B$20,G25<=$B$20) -> TRUE | J25: =IF(H25<>I25,IF(G25=E25,"",D25 + ($B$20-E25)*(F25-D25)/(G25-E25)),"") -> -20 | K25: =IF(H25,1,IF(I25,2,0)) -> 2 | L25: 1 | M25: =IF(K25=0,"",IF(H25,IF(I25,F25,J25),J25)) -> -20 | N25: =IF(K25=0,"",IF(H25,IF(I25,G25,$B$20),$B$20)) -> -13.4625 | O25: =IF(K25<2,"",F25) -> -20 | P25: =IF(K25<2,"",G25) -> 25
A26: 2 | B26: 2 | C26: 3 | D26: =INDEX($D$15:$D$18,B26) -> -20 | E26: =INDEX($E$15:$E$18,B26) -> 25 | F26: =INDEX($D$15:$D$18,C26) -> 20 | G26: =INDEX($E$15:$E$18,C26) -> 25 | H26: =IF($E$7="Above (y >= y_cut)",E26>=$B$20,E26<=$B$20) -> TRUE | I26: =IF($E$7="Above (y >= y_cut)",G26>=$B$20,G26<=$B$20) -> TRUE | J26: =IF(H26<>I26,IF(G26=E26,"",D26 + ($B$20-E26)*(F26-D26)/(G26-E26)),"") | K26: =IF(H26,1,IF(I26,2,0)) -> 1 | L26: =L25+K25 -> 3 | M26: =IF(K26=0,"",IF(H26,IF(I26,F26,J26),J26)) -> 20 | N26: =IF(K26=0,"",IF(H26,IF(I26,G26,$B$20),$B$20)) -> 25 | O26: =IF(K26<2,"",F26) | P26: =IF(K26<2,"",G26)
A27: 3 | B27: 3 | C27: 4 | D27: =INDEX($D$15:$D$18,B27) -> 20 | E27: =INDEX($E$15:$E$18,B27) -> 25 | F27: =INDEX($D$15:$D$18,C27) -> 20 | G27: =INDEX($E$15:$E$18,C27) -> -25 | H27: =IF($E$7="Above (y >= y_cut)",E27>=$B$20,E27<=$B$20) -> TRUE | I27: =IF($E$7="Above (y >= y_cut)",G27>=$B$20,G27<=$B$20) -> FALSE | J27: =IF(H27<>I27,IF(G27=E27,"",D27 + ($B$20-E27)*(F27-D27)/(G27-E27)),"") -> 20 | K27: =IF(H27,1,IF(I27,2,0)) -> 1 | L27: =L26+K26 -> 4 | M27: =IF(K27=0,"",IF(H27,IF(I27,F27,J27),J27)) -> 20 | N27: =IF(K27=0,"",IF(H27,IF(I27,G27,$B$20),$B$20)) -> -13.4625 | O27: =IF(K27<2,"",F27) | P27: =IF(K27<2,"",G27)
A28: 4 | B28: 4 | C28: 1 | D28: =INDEX($D$15:$D$18,B28) -> 20 | E28: =INDEX($E$15:$E$18,B28) -> -25 | F28: =INDEX($D$15:$D$18,C28) -> -20 | G28: =INDEX($E$15:$E$18,C28) -> -25 | H28: =IF($E$7="Above (y >= y_cut)",E28>=$B$20,E28<=$B$20) -> FALSE | I28: =IF($E$7="Above (y >= y_cut)",G28>=$B$20,G28<=$B$20) -> FALSE | J28: =IF(H28<>I28,IF(G28=E28,"",D28 + ($B$20-E28)*(F28-D28)/(G28-E28)),"") | K28: =IF(H28,1,IF(I28,2,0)) -> 0 | L28: =L27+K27 -> 5 | M28: =IF(K28=0,"",IF(H28,IF(I28,F28,J28),J28)) | N28: =IF(K28=0,"",IF(H28,IF(I28,G28,$B$20),$B$20)) | O28: =IF(K28<2,"",F28) | P28: =IF(K28<2,"",G28)
A29: CLOSE | D29: =D25 -> -20 | E29: =E25 -> -25
A30: Total vertices N_out | B30: =SUM($K$25:$K$28) -> 4
A32: Clipped polygon vertices (in traversal order)
A33: k | B33: x_out (in) | C33: y_out (in) | D33: x_out (out) | E33: y_out (out) | F33: Δ | G33: x_term | H33: y_term
A34: 1 | B34: =IF($A34>$B$30,NA(),IF(K34=1,INDEX($M$25:$M$28,J34),INDEX($O$25:$O$28,J34))) -> -20 | C34: =IF($A34>$B$30,NA(),IF(K34=1,INDEX($N$25:$N$28,J34),INDEX($P$25:$P$28,J34))) -> -13.4625 | D34: =IF(ISNA(B34),NA(),B34*$B$12) -> -20 | E34: =IF(ISNA(C34),NA(),C34*$B$12) -> -13.4625 | F34: =IF($A34>$B$30,"",B34*M34-L34*C34) -> -769.25 | G34: =IF($A34>$B$30,"",(B34+L34)*F34) -> 30770 | H34: =IF($A34>$B$30,"",(C34+M34)*F34) -> -8875.2219 | I34: =IF($A34>$B$30,"",LOOKUP($A34,$L$25:$L$28,$A$25:$A$28)) -> 1 | J34: =IF($A34>$B$30,"",MATCH(I34,$A$25:$A$28,0)) -> 1 | K34: =IF($A34>$B$30,"",$A34-INDEX($L$25:$L$28,J34)+1) -> 1 | L34: =IF($A34>$B$30,"",IF($A34<$B$30,B35,$B$34)) -> -20 | M34: =IF($A34>$B$30,"",IF($A34<$B$30,C35,$C$34)) -> 25
A35: 2 | B35: =IF($A35>$B$30,NA(),IF(K35=1,INDEX($M$25:$M$28,J35),INDEX($O$25:$O$28,J35))) -> -20 | C35: =IF($A35>$B$30,NA(),IF(K35=1,INDEX($N$25:$N$28,J35),INDEX($P$25:$P$28,J35))) -> 25 | D35: =IF(ISNA(B35),NA(),B35*$B$12) -> -20 | E35: =IF(ISNA(C35),NA(),C35*$B$12) -> 25 | F35: =IF($A35>$B$30,"",B35*M35-L35*C35) -> -1000 | G35: =IF($A35>$B$30,"",(B35+L35)*F35) -> 0 | H35: =IF($A35>$B$30,"",(C35+M35)*F35) -> -50000 | I35: =IF($A35>$B$30,"",LOOKUP($A35,$L$25:$L$28,$A$25:$A$28)) -> 1 | J35: =IF($A35>$B$30,"",MATCH(I35,$A$25:$A$28,0)) -> 1 | K35: =IF($A35>$B$30,"",$A35-INDEX($L$25:$L$28,J35)+1) -> 2 | L35: =IF($A35>$B$30,"",IF($A35<$B$30,B36,$B$34)) -> 20 | M35: =IF($A35>$B$30,"",IF($A35<$B$30,C36,$C$34)) -> 25
A36: 3 | B36: =IF($A36>$B$30,NA(),IF(K36=1,INDEX($M$25:$M$28,J36),INDEX($O$25:$O$28,J36))) -> 20 | C36: =IF($A36>$B$30,NA(),IF(K36=1,INDEX($N$25:$N$28,J36),INDEX($P$25:$P$28,J36))) -> 25 | D36: =IF(ISNA(B36),NA(),B36*$B$12) -> 20 | E36: =IF(ISNA(C36),NA(),C36*$B$12) -> 25 | F36: =IF($A36>$B$30,"",B36*M36-L36*C36) -> -769.25 | G36: =IF($A36>$B$30,"",(B36+L36)*F36) -> -30770 | H36: =IF($A36>$B$30,"",(C36+M36)*F36) -> -8875.2219 | I36: =IF($A36>$B$30,"",LOOKUP($A36,$L$25:$L$28,$A$25:$A$28)) -> 2 | J36: =IF($A36>$B$30,"",MATCH(I36,$A$25:$A$28,0)) -> 2 | K36: =IF($A36>$B$30,"",$A36-INDEX($L$25:$L$28,J36)+1) -> 1 | L36: =IF($A36>$B$30,"",IF($A36<$B$30,B37,$B$34)) -> 20 | M36: =IF($A36>$B$30,"",IF($A36<$B$30,C37,$C$34)) -> -13.4625
A37: 4 | B37: =IF($A37>$B$30,NA(),IF(K37=1,INDEX($M$25:$M$28,J37),INDEX($O$25:$O$28,J37))) -> 20 | C37: =IF($A37>$B$30,NA(),IF(K37=1,INDEX($N$25:$N$28,J37),INDEX($P$25:$P$28,J37))) -> -13.4625 | D37: =IF(ISNA(B37),NA(),B37*$B$12) -> 20 | E37: =IF(ISNA(C37),NA(),C37*$B$12) -> -13.4625 | F37: =IF($A37>$B$30,"",B37*M37-L37*C37) -> -538.5 | G37: =IF($A37>$B$30,"",(B37+L37)*F37) -> 0 | H37: =IF($A37>$B$30,"",(C37+M37)*F37) -> 14499.112 | I37: =IF($A37>$B$30,"",LOOKUP($A37,$L$25:$L$28,$A$25:$A$28)) -> 3 | J37: =IF($A37>$B$30,"",MATCH(I37,$A$25:$A$28,0)) -> 3 | K37: =IF($A37>$B$30,"",$A37-INDEX($L$25:$L$28,J37)+1) -> 1 | L37: =IF($A37>$B$30,"",IF($A37<$B$30,B38,$B$34)) -> -20 | M37: =IF($A37>$B$30,"",IF($A37<$B$30,C38,$C$34)) -> -13.4625
A38: 5 | B38: =IF($A38>$B$30,NA(),IF(K38=1,INDEX($M$25:$M$28,J38),INDEX($O$25:$O$28,J38))) -> #N/A | C38: =IF($A38>$B$30,NA(),IF(K38=1,INDEX($N$25:$N$28,J38),INDEX($P$25:$P$28,J38))) -> #N/A | D38: =IF(ISNA(B38),NA(),B38*$B$12) -> #N/A | E38: =IF(ISNA(C38),NA(),C38*$B$12) -> #N/A | F38: =IF($A38>$B$30,"",B38*M38-L38*C38) | G38: =IF($A38>$B$30,"",(B38+L38)*F38) | H38: =IF($A38>$B$30,"",(C38+M38)*F38) | I38: =IF($A38>$B$30,"",LOOKUP($A38,$L$25:$L$28,$A$25:$A$28)) | J38: =IF($A38>$B$30,"",MATCH(I38,$A$25:$A$28,0)) | K38: =IF($A38>$B$30,"",$A38-INDEX($L$25:$L$28,J38)+1) | L38: =IF($A38>$B$30,"",IF($A38<$B$30,B39,$B$34)) | M38: =IF($A38>$B$30,"",IF($A38<$B$30,C39,$C$34))
A39: 6 | B39: =IF($A39>$B$30,NA(),IF(K39=1,INDEX($M$25:$M$28,J39),INDEX($O$25:$O$28,J39))) -> #N/A | C39: =IF($A39>$B$30,NA(),IF(K39=1,INDEX($N$25:$N$28,J39),INDEX($P$25:$P$28,J39))) -> #N/A | D39: =IF(ISNA(B39),NA(),B39*$B$12) -> #N/A | E39: =IF(ISNA(C39),NA(),C39*$B$12) -> #N/A | F39: =IF($A39>$B$30,"",B39*M39-L39*C39) | G39: =IF($A39>$B$30,"",(B39+L39)*F39) | H39: =IF($A39>$B$30,"",(C39+M39)*F39) | I39: =IF($A39>$B$30,"",LOOKUP($A39,$L$25:$L$28,$A$25:$A$28)) | J39: =IF($A39>$B$30,"",MATCH(I39,$A$25:$A$28,0)) | K39: =IF($A39>$B$30,"",$A39-INDEX($L$25:$L$28,J39)+1) | L39: =IF($A39>$B$30,"",IF($A39<$B$30,B40,$B$34)) | M39: =IF($A39>$B$30,"",IF($A39<$B$30,C40,$C$34))
A40: 7 | B40: =IF($A40>$B$30,NA(),IF(K40=1,INDEX($M$25:$M$28,J40),INDEX($O$25:$O$28,J40))) -> #N/A | C40: =IF($A40>$B$30,NA(),IF(K40=1,INDEX($N$25:$N$28,J40),INDEX($P$25:$P$28,J40))) -> #N/A | D40: =IF(ISNA(B40),NA(),B40*$B$12) -> #N/A | E40: =IF(ISNA(C40),NA(),C40*$B$12) -> #N/A | F40: =IF($A40>$B$30,"",B40*M40-L40*C40) | G40: =IF($A40>$B$30,"",(B40+L40)*F40) | H40: =IF($A40>$B$30,"",(C40+M40)*F40) | I40: =IF($A40>$B$30,"",LOOKUP($A40,$L$25:$L$28,$A$25:$A$28)) | J40: =IF($A40>$B$30,"",MATCH(I40,$A$25:$A$28,0)) | K40: =IF($A40>$B$30,"",$A40-INDEX($L$25:$L$28,J40)+1) | L40: =IF($A40>$B$30,"",IF($A40<$B$30,B41,$B$34)) | M40: =IF($A40>$B$30,"",IF($A40<$B$30,C41,$C$34))
A41: 8 | B41: =IF($A41>$B$30,NA(),IF(K41=1,INDEX($M$25:$M$28,J41),INDEX($O$25:$O$28,J41))) -> #N/A | C41: =IF($A41>$B$30,NA(),IF(K41=1,INDEX($N$25:$N$28,J41),INDEX($P$25:$P$28,J41))) -> #N/A | D41: =IF(ISNA(B41),NA(),B41*$B$12) -> #N/A | E41: =IF(ISNA(C41),NA(),C41*$B$12) -> #N/A | F41: =IF($A41>$B$30,"",B41*M41-L41*C41) | G41: =IF($A41>$B$30,"",(B41+L41)*F41) | H41: =IF($A41>$B$30,"",(C41+M41)*F41) | I41: =IF($A41>$B$30,"",LOOKUP($A41,$L$25:$L$28,$A$25:$A$28)) | J41: =IF($A41>$B$30,"",MATCH(I41,$A$25:$A$28,0)) | K41: =IF($A41>$B$30,"",$A41-INDEX($L$25:$L$28,J41)+1) | L41: =IF($A41>$B$30,"",IF($A41<$B$30,B42,$B$34)) | M41: =IF($A41>$B$30,"",IF($A41<$B$30,C42,$C$34))
A42: close | B42: =IF($B$30<1,NA(),B34) -> -20 | C42: =IF($B$30<1,NA(),C34) -> -13.4625 | D42: =IF($B$30<1,NA(),D34) -> -20 | E42: =IF($B$30<1,NA(),E34) -> -13.4625
A44: Results
...

Sheet R2
A1: Rotated Rectangle + Horizontal Cut (No VBA) | D1: 2 | E1: /20
A2: Cut position λ (0→y_min, 1→y_max) | B2: =D1/20 -> 0.1 | D2: β1= | E2: =check!G5 -> 0.85
A3: Input unit | B3: cm | D3: Output unit | E3: cm
A4: Width B (input unit) | B4: =check!C3 -> 50
A5: Deepth D (input unit) | B5: =check!C4 -> 40
A6: Rotate rectangle θ (deg, about origin) | B6: =90+check!C13 -> 90 | H6: cosθ | I6: sinθ
A7: Cut position 1-(1-λ)β1 | B7: =IF(B2=0,0,1-(1-B2)*E2) -> 0.235 | D7: Keep side | E7: Above (y >= y_cut) | H7: =COS(RADIANS($B$6)) -> 6.1257423e-17 | I7: =SIN(RADIANS($B$6)) -> 1
A9: Unit scales (mm per unit)
A10: s_in | B10: =IF($B$3="mm",1,IF($B$3="cm",10,IF($B$3="m",1000,1))) -> 10
A11: s_out | B11: =IF($E$3="mm",1,IF($E$3="cm",10,IF($E$3="m",1000,1))) -> 10
A12: len_in_to_out | B12: =$B$10/$B$11 -> 1
A13: Rotated rectangle vertices (after rotation θ)
A14: Corner | B14: x0 | C14: y0 | D14: x_rot | E14: y_rot | F14: Inside?
A15: 1 | B15: =IF(A15=1,-$B$4/2,IF(A15=2,$B$4/2,IF(A15=3,$B$4/2,-$B$4/2))) -> -25 | C15: =IF(A15=1,$B$5/2,IF(A15=2,$B$5/2,IF(A15=3,-$B$5/2,-$B$5/2))) -> 20 | D15: =(B15)*$H$7 - (C15)*$I$7 -> -20 | E15: =(B15)*$I$7 + (C15)*$H$7 -> -25 | F15: =IF($E$7="Above (y >= y_cut)",E15>=$B$20,E15<=$B$20) -> FALSE
A16: 2 | B16: =IF(A16=1,-$B$4/2,IF(A16=2,$B$4/2,IF(A16=3,$B$4/2,-$B$4/2))) -> 25 | C16: =IF(A16=1,$B$5/2,IF(A16=2,$B$5/2,IF(A16=3,-$B$5/2,-$B$5/2))) -> 20 | D16: =(B16)*$H$7 - (C16)*$I$7 -> -20 | E16: =(B16)*$I$7 + (C16)*$H$7 -> 25 | F16: =IF($E$7="Above (y >= y_cut)",E16>=$B$20,E16<=$B$20) -> TRUE
A17: 3 | B17: =IF(A17=1,-$B$4/2,IF(A17=2,$B$4/2,IF(A17=3,$B$4/2,-$B$4/2))) -> 25 | C17: =IF(A17=1,$B$5/2,IF(A17=2,$B$5/2,IF(A17=3,-$B$5/2,-$B$5/2))) -> -20 | D17: =(B17)*$H$7 - (C17)*$I$7 -> 20 | E17: =(B17)*$I$7 + (C17)*$H$7 -> 25 | F17: =IF($E$7="Above (y >= y_cut)",E17>=$B$20,E17<=$B$20) -> TRUE
A18: 4 | B18: =IF(A18=1,-$B$4/2,IF(A18=2,$B$4/2,IF(A18=3,$B$4/2,-$B$4/2))) -> -25 | C18: =IF(A18=1,$B$5/2,IF(A18=2,$B$5/2,IF(A18=3,-$B$5/2,-$B$5/2))) -> -20 | D18: =(B18)*$H$7 - (C18)*$I$7 -> 20 | E18: =(B18)*$I$7 + (C18)*$H$7 -> -25 | F18: =IF($E$7="Above (y >= y_cut)",E18>=$B$20,E18<=$B$20) -> FALSE
G19: x | H19: y | I19: L
A20: y_cut (input unit) | B20: =$B$21 + $B$7*($D$21-$B$21) -> -13.25 | C20: y_cut (output unit) | D20: =$B$20*$B$12 -> -13.25 | E20: Nature ax= | F20: =$B$21 + $B$2*($D$21-$B$21) -> -20 | G20: =MIN(D15:D18) -> -20 | H20: =F20 -> -20 | I20: =D21-F20 -> 45
A21: y_min (input unit) | B21: =MIN($E$15:$E$18) -> -25 | C21: y_max (input unit) | D21: =MAX($E$15:$E$18) -> 25 | G21: =MAX(D15:D18) -> 20 | H21: =F20 -> -20
A23: Clipping edges (Sutherland–Hodgman for y >=/<= y_cut)
A24: Edge | B24: S idx | C24: E idx | D24: xS | E24: yS | F24: xE | G24: yE | H24: inS | I24: inE | J24: xInt | K24: nOut | L24: posStart | M24: xOut1 | N24: yOut1 | O24: xOut2 | P24: yOut2
A25: 1 | B25: 1 | C25: 2 | D25: =INDEX($D$15:$D$18,B25) -> -20 | E25: =INDEX($E$15:$E$18,B25) -> -25 | F25: =INDEX($D$15:$D$18,C25) -> -20 | G25: =INDEX($E$15:$E$18,C25) -> 25 | H25: =IF($E$7="Above (y >= y_cut)",E25>=$B$20,E25<=$B$20) -> FALSE | I25: =IF($E$7="Above (y >= y_cut)",G25>=$B$20,G25<=$B$20) -> TRUE | J25: =IF(H25<>I25,IF(G25=E25,"",D25 + ($B$20-E25)*(F25-D25)/(G25-E25)),"") -> -20 | K25: =IF(H25,1,IF(I25,2,0)) -> 2 | L25: 1 | M25: =IF(K25=0,"",IF(H25,IF(I25,F25,J25),J25)) -> -20 | N25: =IF(K25=0,"",IF(H25,IF(I25,G25,$B$20),$B$20)) -> -13.25 | O25: =IF(K25<2,"",F25) -> -20 | P25: =IF(K25<2,"",G25) -> 25
A26: 2 | B26: 2 | C26: 3 | D26: =INDEX($D$15:$D$18,B26) -> -20 | E26: =INDEX($E$15:$E$18,B26) -> 25 | F26: =INDEX($D$15:$D$18,C26) -> 20 | G26: =INDEX($E$15:$E$18,C26) -> 25 | H26: =IF($E$7="Above (y >= y_cut)",E26>=$B$20,E26<=$B$20) -> TRUE | I26: =IF($E$7="Above (y >= y_cut)",G26>=$B$20,G26<=$B$20) -> TRUE | J26: =IF(H26<>I26,IF(G26=E26,"",D26 + ($B$20-E26)*(F26-D26)/(G26-E26)),"") | K26: =IF(H26,1,IF(I26,2,0)) -> 1 | L26: =L25+K25 -> 3 | M26: =IF(K26=0,"",IF(H26,IF(I26,F26,J26),J26)) -> 20 | N26: =IF(K26=0,"",IF(H26,IF(I26,G26,$B$20),$B$20)) -> 25 | O26: =IF(K26<2,"",F26) | P26: =IF(K26<2,"",G26)
A27: 3 | B27: 3 | C27: 4 | D27: =INDEX($D$15:$D$18,B27) -> 20 | E27: =INDEX($E$15:$E$18,B27) -> 25 | F27: =INDEX($D$15:$D$18,C27) -> 20 | G27: =INDEX($E$15:$E$18,C27) -> -25 | H27: =IF($E$7="Above (y >= y_cut)",E27>=$B$20,E27<=$B$20) -> TRUE | I27: =IF($E$7="Above (y >= y_cut)",G27>=$B$20,G27<=$B$20) -> FALSE | J27: =IF(H27<>I27,IF(G27=E27,"",D27 + ($B$20-E27)*(F27-D27)/(G27-E27)),"") -> 20 | K27: =IF(H27,1,IF(I27,2,0)) -> 1 | L27: =L26+K26 -> 4 | M27: =IF(K27=0,"",IF(H27,IF(I27,F27,J27),J27)) -> 20 | N27: =IF(K27=0,"",IF(H27,IF(I27,G27,$B$20),$B$20)) -> -13.25 | O27: =IF(K27<2,"",F27) | P27: =IF(K27<2,"",G27)
A28: 4 | B28: 4 | C28: 1 | D28: =INDEX($D$15:$D$18,B28) -> 20 | E28: =INDEX($E$15:$E$18,B28) -> -25 | F28: =INDEX($D$15:$D$18,C28) -> -20 | G28: =INDEX($E$15:$E$18,C28) -> -25 | H28: =IF($E$7="Above (y >= y_cut)",E28>=$B$20,E28<=$B$20) -> FALSE | I28: =IF($E$7="Above (y >= y_cut)",G28>=$B$20,G28<=$B$20) -> FALSE | J28: =IF(H28<>I28,IF(G28=E28,"",D28 + ($B$20-E28)*(F28-D28)/(G28-E28)),"") | K28: =IF(H28,1,IF(I28,2,0)) -> 0 | L28: =L27+K27 -> 5 | M28: =IF(K28=0,"",IF(H28,IF(I28,F28,J28),J28)) | N28: =IF(K28=0,"",IF(H28,IF(I28,G28,$B$20),$B$20)) | O28: =IF(K28<2,"",F28) | P28: =IF(K28<2,"",G28)
A29: CLOSE | D29: =D25 -> -20 | E29: =E25 -> -25
A30: Total vertices N_out | B30: =SUM($K$25:$K$28) -> 4
A32: Clipped polygon vertices (in traversal order)
A33: k | B33: x_out (in) | C33: y_out (in) | D33: x_out (out) | E33: y_out (out) | F33: Δ | G33: x_term | H33: y_term
A34: 1 | B34: =IF($A34>$B$30,NA(),IF(K34=1,INDEX($M$25:$M$28,J34),INDEX($O$25:$O$28,J34))) -> -20 | C34: =IF($A34>$B$30,NA(),IF(K34=1,INDEX($N$25:$N$28,J34),INDEX($P$25:$P$28,J34))) -> -13.25 | D34: =IF(ISNA(B34),NA(),B34*$B$12) -> -20 | E34: =IF(ISNA(C34),NA(),C34*$B$12) -> -13.25 | F34: =IF($A34>$B$30,"",B34*M34-L34*C34) -> -765 | G34: =IF($A34>$B$30,"",(B34+L34)*F34) -> 30600 | H34: =IF($A34>$B$30,"",(C34+M34)*F34) -> -8988.75 | I34: =IF($A34>$B$30,"",LOOKUP($A34,$L$25:$L$28,$A$25:$A$28)) -> 1 | J34: =IF($A34>$B$30,"",MATCH(I34,$A$25:$A$28,0)) -> 1 | K34: =IF($A34>$B$30,"",$A34-INDEX($L$25:$L$28,J34)+1) -> 1 | L34: =IF($A34>$B$30,"",IF($A34<$B$30,B35,$B$34)) -> -20 | M34: =IF($A34>$B$30,"",IF($A34<$B$30,C35,$C$34)) -> 25
